Workbook
Name B0__adatok_excel_fájljának_neve: "BPI_adatok.xlsx"
Name B0__adatok_munkafüzetének_neve: "List1"
Name B0__adatokban_oszlopneve_a_kávé_értékesítéseknek: "Kávé darabszám"
Name B0__adatokban_oszlopneve_a_sém_kódoknak: "Sém Kód"
Name B0__adatokban_oszlopneve_az_azonosítóknak: "Kút Kód"
Name B0__sorának_száma_a_fejléceknek: 1
Name D1__adatok_munkafüzetének_referenciája: "["&B0__adatok_excel_fájljának_neve&"]"&B0__adatok_munkafüzetének_neve
Name D1__adatokban_fejlécek_tartománya: B0__sorának_száma_a_fejléceknek&":"&B0__sorának_száma_a_fejléceknek
Name D2__adatokban_címe_a_fejlécekben_a_kávé_értékesítések_cellájának: ADDRESS(B0__sorának_száma_a_fejléceknek,MATCH(B0__adatokban_oszlopneve_a_kávé_értékesítéseknek,INDIRECT(D1__adatok_munkafüzetének_referenciája&"!"&D1__adatokban_fejlécek_tartománya),0))
Name D2__adatokban_címe_a_fejlécekben_az_azonosítók_cellájának: ADDRESS(B0__sorának_száma_a_fejléceknek,MATCH(B0__adatokban_oszlopneve_az_azonosítóknak,INDIRECT(D1__adatok_munkafüzetének_referenciája&"!"&D1__adatokban_fejlécek_tartománya),0))
Name D3__adatokban_oszlopának_neve_a_kávé_értékesítéseknek: CHAR(COLUMN(INDIRECT(D2__adatokban_címe_a_fejlécekben_a_kávé_értékesítések_cellájának))+64)
Name D3__oszlopának_neve_az_azonosítóknak: CHAR(COLUMN(INDIRECT(D2__adatokban_címe_a_fejlécekben_az_azonosítók_cellájának))+64)
Name fejlécek_sora: INDIRECT(INDIRECT(B0__adatok_excel_fájljának_neve))
Name gastro_selejtszám_oszlop: [1]List1!$F$2:$F$379
Name hot_dog_on_guidance_oszlop: [1]List1!#REF!
Name kávé_darabszám_oszlop: [1]List1!$G$2:$G$379
Name kávé_hot_dog_szendvics_pizza_wrap_sémKód_oszlopa: '[2]Forgalom és raktárkészlet'!$J$5:$J$1181
Name Kút_kategóriája: _xlfn.XLOOKUP('SÉM-Riport'!Kútkód,'Data 2024'!$B$2:$B$380,'Data 2024'!$D$2:$D$380)
Name Kút_kategóriája: _xlfn.XLOOKUP(Riport!Kútkód,'Data 2024'!$A$2:$A$380,'Data 2024'!$D$2:$D$380)
Name Kútkód: Riport!$C$1
Name Kútkód: 'SÉM-Riport'!$C$1
Name kútkód_oszlop: [1]List1!#REF!
Name pizza_darabszám_oszlop: [1]List1!$L$2:$L$379
Name sandwich_planner_on_guidance_oszlop: [1]List1!#REF!
Name SÉM: #REF!
Name sémkód_oszlop: [1]List1!#REF!
Name sorok_száma_az_adatokban: MAX(ROW(Riport!XFB:XFB)*(Riport!XFB:XFB<>""))
Name sorok_száma_az_adatokban: MAX(ROW('SÉM-Riport'!XFB:XFB)*('SÉM-Riport'!XFB:XFB<>""))
Name sorok_száma_az_adatokban: MAX(ROW(#REF!)*(#REF!<>""))

Sheet Data 2024
A1: Service Enabling System Code | B1: X Code | C1: Address | D1: Region | E1: Total Units Sold | F1: Coffee Units Sold | G1: Sandwich Units Sold | H1: Hot-Dog Units Sold | I1: Coffee Relative Sales to Gastro | J1: Sandwich Relative Sales to Gastro | K1: Hot-Dog Relative Sales to Gastro | L1: Gastro Net Waste | M1: Gastro Net Sales | N1: Drygoods Net Waste | O1: Drygoods Net Sales | P1: Gastro Relative Waste to Total Sales | Q1: Drygoods Relative Waste to Total Sales
A2: 2476400 | B2: 422914 | C2: Address 1 | D2: Region 1 | E2: 255272 | F2: 18814 | G2: 0 | H2: 24863 | I2: =F2/$E2 -> 0.073701777 | J2: =G2/$E2 -> 0 | K2: =H2/$E2 -> 0.09739807 | L2: -1091068.3 | M2: 16679164 | N2: -2078001.3 | O2: 56179730 | P2: =ABS(L2/M2) -> 0.065415045 | Q2: =ABS(N2/O2) -> 0.036988452
A3: 2479700 | B3: 298881 | C3: Address 2 | D3: Region 2 | E3: 244384 | F3: 16188 | G3: 3418 | H3: 19772 | I3: =F3/$E3 -> 0.066240016 | J3: =G3/$E3 -> 0.013986186 | K3: =H3/$E3 -> 0.08090546 | L3: -3053288.9 | M3: 15194092 | N3: -2105215.2 | O3: 36784412 | P3: =ABS(L3/M3) -> 0.20095238 | Q3: =ABS(N3/O3) -> 0.057231177
A4: 2496700 | B4: 683860 | C4: Address 3 | D4: Region 1 | E4: 167983 | F4: 18596 | G4: 2996 | H4: 18127 | I4: =F4/$E4 -> 0.11070168 | J4: =G4/$E4 -> 0.017835138 | K4: =H4/$E4 -> 0.10790973 | L4: -957793.15 | M4: 13535084 | N4: -990494.97 | O4: 20315551 | P4: =ABS(L4/M4) -> 0.070763737 | Q4: =ABS(N4/O4) -> 0.048755506
A5: 2506300 | B5: 538107 | C5: Address 4 | D5: Region 2 | E5: 190045 | F5: 22606 | G5: 4308 | H5: 22402 | I5: =F5/$E5 -> 0.11895077 | J5: =G5/$E5 -> 0.022668315 | K5: =H5/$E5 -> 0.11787734 | L5: -3456817.2 | M5: 25635737 | N5: -1282625.4 | O5: 56812064 | P5: =ABS(L5/M5) -> 0.13484369 | Q5: =ABS(N5/O5) -> 0.022576637
A6: 2515100 | B6: 460794 | C6: Address 5 | D6: Region 2 | E6: 196344 | F6: 24361 | G6: 6556 | H6: 21812 | I6: =F6/$E6 -> 0.12407306 | J6: =G6/$E6 -> 0.033390376 | K6: =H6/$E6 -> 0.11109074 | L6: -2972137.6 | M6: 21890238 | N6: -934213.46 | O6: 28602301 | P6: =ABS(L6/M6) -> 0.13577457 | Q6: =ABS(N6/O6) -> 0.032662179
A7: 2526600 | B7: 941576 | C7: Address 6 | D7: Region 1 | E7: 109413 | F7: 11289 | G7: 1271 | H7: 16230 | I7: =F7/$E7 -> 0.10317787 | J7: =G7/$E7 -> 0.011616536 | K7: =H7/$E7 -> 0.14833703 | L7: -1658093.2 | M7: 11554653 | N7: -1982775.3 | O7: 15517225 | P7: =ABS(L7/M7) -> 0.14350004 | Q7: =ABS(N7/O7) -> 0.12777899
A8: 2551300 | B8: 503516 | C8: Address 7 | D8: Region 1 | E8: 165545 | F8: 14211 | G8: 2134 | H8: 21503 | I8: =F8/$E8 -> 0.085843728 | J8: =G8/$E8 -> 0.012890755 | K8: =H8/$E8 -> 0.12989217 | L8: -1736038.6 | M8: 15473643 | N8: -2103475 | O8: 23506256 | P8: =ABS(L8/M8) -> 0.11219327 | Q8: =ABS(N8/O8) -> 0.089485755
A9: 2553500 | B9: 391003 | C9: Address 8 | D9: Region 2 | E9: 158937 | F9: 13019 | G9: 3228 | H9: 18536 | I9: =F9/$E9 -> 0.081912959 | J9: =G9/$E9 -> 0.020309934 | K9: =H9/$E9 -> 0.11662483 | L9: -3816889.9 | M9: 14217567 | N9: -1896213 | O9: 16230914 | P9: =ABS(L9/M9) -> 0.26846294 | Q9: =ABS(N9/O9) -> 0.11682724
A10: 2555200 | B10: 702455 | C10: Address 9 | D10: Region 2 | E10: 195575 | F10: 20767 | G10: 5136 | H10: 27254 | I10: =F10/$E10 -> 0.10618433 | J10: =G10/$E10 -> 0.026261025 | K10: =H10/$E10 -> 0.13935319 | L10: -3685698.1 | M10: 23398510 | N10: -5039521.2 | O10: 32866387 | P10: =ABS(L10/M10) -> 0.1575185 | Q10: =ABS(N10/O10) -> 0.15333359
A11: 2581500 | B11: 296777 | C11: Address 10 | D11: Region 2 | E11: 365322 | F11: 39189 | G11: 7651 | H11: 60242 | I11: =F11/$E11 -> 0.10727249 | J11: =G11/$E11 -> 0.020943168 | K11: =H11/$E11 -> 0.1649011 | L11: -3266907 | M11: 46428658 | N11: -2566190 | O11: 84220818 | P11: =ABS(L11/M11) -> 0.070364019 | Q11: =ABS(N11/O11) -> 0.030469782
A12: 2582200 | B12: 560301 | C12: Address 11 | D12: Region 1 | E12: 165464 | F12: 15304 | G12: 2903 | H12: 24544 | I12: =F12/$E12 -> 0.092491418 | J12: =G12/$E12 -> 0.017544602 | K12: =H12/$E12 -> 0.14833438 | L12: -1853174.9 | M12: 18000214 | N12: -1767937.8 | O12: 33188290 | P12: =ABS(L12/M12) -> 0.10295294 | Q12: =ABS(N12/O12) -> 0.053269927
A13: 2583300 | B13: 1107718 | C13: Address 12 | D13: Region 12 | E13: 98824 | F13: 11025 | G13: 0 | H13: 2282 | I13: =F13/$E13 -> 0.11156197 | J13: =G13/$E13 -> 0 | K13: =H13/$E13 -> 0.023091557 | L13: -129813.16 | M13: 3415142.1 | N13: -929459.53 | O13: 44295672 | P13: =ABS(L13/M13) -> 0.038011057 | Q13: =ABS(N13/O13) -> 0.020983078
... A22: 2608800 | B22: 273444 | C22: Address 21 | D22: Region 1 | E22: 281843 | F22: 23801 | G22: 4652 | H22: 36864 | I22: =F22/$E22 -> 0.084447724 | J22: =G22/$E22 -> 0.016505643 | K22: =H22/$E22 -> 0.13079622 | L22: -1342212.7 | M22: 28357226 | N22: -403957.39 | O22: 57317938 | P22: =ABS(L22/M22) -> 0.047332301 | Q22: =ABS(N22/O22) -> 0.0070476609
A23: 2609900 | B23: 443514 | C23: Address 22 | D23: Region 12 | E23: 56408 | F23: 4068 | G23: 0 | H23: 0 | I23: =F23/$E23 -> 0.07211743 | J23: =G23/$E23 -> 0 | K23: =H23/$E23 -> 0 | L23: -30476.378 | M23: 263.9147 | N23: -1098904.8 | O23: 10885054 | P23: 0 | Q23: =ABS(N23/O23) -> 0.10095538
A24: 2611000 | B24: 258664 | C24: Address 23 | D24: Region 1 | E24: 129735 | F24: 9138 | G24: 0 | H24: 15327 | I24: =F24/$E24 -> 0.070435889 | J24: =G24/$E24 -> 0 | K24: =H24/$E24 -> 0.11814083 | L24: -836128.93 | M24: 9599290.7 | N24: -1800017.5 | O24: 18349135 | P24: =ABS(L24/M24) -> 0.087103199 | Q24: =ABS(N24/O24) -> 0.098098219
A25: 2613200 | B25: 1038760 | C25: Address 24 | D25: Region 2 | E25: 294137 | F25: 37204 | G25: 14171 | H25: 40189 | I25: =F25/$E25 -> 0.12648528 | J25: =G25/$E25 -> 0.04817823 | K25: =H25/$E25 -> 0.13663361 | L25: -4257591.7 | M25: 38644234 | N25: -1606088.7 | O25: 52974539 | P25: =ABS(L25/M25) -> 0.11017405 | Q25: =ABS(N25/O25) -> 0.030318125
A26: 2614300 | B26: 812609 | C26: Address 25 | D26: Region 2 | E26: 201032 | F26: 22647 | G26: 5085 | H26: 26281 | I26: =F26/$E26 -> 0.11265371 | J26: =G26/$E26 -> 0.02529448 | K26: =H26/$E26 -> 0.13073043 | L26: -2141905.8 | M26: 19539548 | N26: -1278065.7 | O26: 24074012 | P26: =ABS(L26/M26) -> 0.109619 | Q26: =ABS(N26/O26) -> 0.05308902
A27: 2615500 | B27: 287945 | C27: Address 26 | D27: Region 1 | E27: 131767 | F27: 13228 | G27: 957 | H27: 16296 | I27: =F27/$E27 -> 0.10038932 | J27: =G27/$E27 -> 0.00726282 | K27: =H27/$E27 -> 0.12367285 | L27: -1270189.8 | M27: 10814729 | N27: -1287626.6 | O27: 20849030 | P27: =ABS(L27/M27) -> 0.11744999 | Q27: =ABS(N27/O27) -> 0.061759543
A28: 2616200 | B28: 526743 | C28: Address 27 | D28: Region 2 | E28: 226465 | F28: 20698 | G28: 4851 | H28: 25823 | I28: =F28/$E28 -> 0.091396021 | J28: =G28/$E28 -> 0.021420529 | K28: =H28/$E28 -> 0.11402645 | L28: -3133117.3 | M28: 22037959 | N28: -822527.73 | O28: 23800167 | P28: =ABS(L28/M28) -> 0.14216912 | Q28: =ABS(N28/O28) -> 0.034559746
A29: 2618400 | B29: 277804 | C29: Address 28 | D29: Region 2 | E29: 237808 | F29: 17253 | G29: 2900 | H29: 19476 | I29: =F29/$E29 -> 0.072550124 | J29: =G29/$E29 -> 0.012194712 | K29: =H29/$E29 -> 0.081898002 | L29: -3129523.2 | M29: 14946273 | N29: -938458.59 | O29: 24642874 | P29: =ABS(L29/M29) -> 0.20938486 | Q29: =ABS(N29/O29) -> 0.038082351
A30: 2621700 | B30: 659558 | C30: Address 29 | D30: Region 2 | E30: 123287 | F30: 16754 | G30: 5119 | H30: 19738 | I30: =F30/$E30 -> 0.1358943 | J30: =G30/$E30 -> 0.041521004 | K30: =H30/$E30 -> 0.16009798 | L30: -2605326.9 | M30: 17403500 | N30: -1770350 | O30: 22703154 | P30: =ABS(L30/M30) -> 0.14970132 | Q30: =ABS(N30/O30) -> 0.077978154
A31: 2622800 | B31: 608420 | C31: Address 30 | D31: Region 1 | E31: 176568 | F31: 15807 | G31: 1442 | H31: 26902 | I31: =F31/$E31 -> 0.089523583 | J31: =G31/$E31 -> 0.0081668252 | K31: =H31/$E31 -> 0.15236056 | L31: -1244280.7 | M31: 17487395 | N31: -575514.27 | O31: 39914422 | P31: =ABS(L31/M31) -> 0.071153005 | Q31: =ABS(N31/O31) -> 0.014418705
A32: 2629100 | B32: 322866 | C32: Address 31 | D32: Region 1 | E32: 207747 | F32: 16935 | G32: 2182 | H32: 26005 | I32: =F32/$E32 -> 0.081517423 | J32: =G32/$E32 -> 0.01050316 | K32: =H32/$E32 -> 0.1251763 | L32: -1080559.9 | M32: 17787341 | N32: -1729608.8 | O32: 23774287 | P32: =ABS(L32/M32) -> 0.060748816 | Q32: =ABS(N32/O32) -> 0.072751238
A33: 2631200 | B33: 1124162 | C33: Address 32 | D33: Region 1 | E33: 150934 | F33: 11525 | G33: 860 | H33: 14879 | I33: =F33/$E33 -> 0.076357878 | J33: =G33/$E33 -> 0.0056978547 | K33: =H33/$E33 -> 0.098579512 | L33: -1114963.9 | M33: 9779588.6 | N33: -850221.81 | O33: 19309052 | P33: =ABS(L33/M33) -> 0.11400928 | Q33: =ABS(N33/O33) -> 0.044032293
A34: 3080400 | B34: 989631 | C34: Address 33 | D34: Region 1 | E34: 242867 | F34: 28374 | G34: 3096 | H34: 35760 | I34: =F34/$E34 -> 0.11682938 | J34: =G34/$E34 -> 0.012747718 | K34: =H34/$E34 -> 0.14724108 | L34: -1382672.3 | M34: 24757223 | N34: -973364.13 | O34: 25159068 | P34: =ABS(L34/M34) -> 0.055849248 | Q34: =ABS(N34/O34) -> 0.038688401
A35: 3085200 | B35: 614538 | C35: Address 34 | D35: Region 2 | E35: 318407 | F35: 36672 | G35: 6731 | H35: 52760 | I35: =F35/$E35 -> 0.11517335 | J35: =G35/$E35 -> 0.021139611 | K35: =H35/$E35 -> 0.16569987 | L35: -2568420.7 | M35: 44152536 | N35: -1843153.3 | O35: 57572533 | P35: =ABS(L35/M35) -> 0.058171532 | Q35: =ABS(N35/O35) -> 0.032014456
... A62: 3188500 | B62: 666163 | C62: Address 61 | D62: Region 2 | E62: 256722 | F62: 22910 | G62: 4877 | H62: 24986 | I62: =F62/$E62 -> 0.089240501 | J62: =G62/$E62 -> 0.018997203 | K62: =H62/$E62 -> 0.09732707 | L62: -2771370.1 | M62: 22432892 | N62: -1381547 | O62: 35153150 | P62: =ABS(L62/M62) -> 0.12354047 | Q62: =ABS(N62/O62) -> 0.039300803
A63: 3189200 | B63: 398761 | C63: Address 62 | D63: Region 12 | E63: 95153 | F63: 4186 | G63: 0 | H63: 0 | I63: =F63/$E63 -> 0.043992307 | J63: =G63/$E63 -> 0 | K63: =H63/$E63 -> 0 | L63: 0 | M63: 0 | N63: -99576.465 | O63: 8535178.8 | P63: 0 | Q63: =ABS(N63/O63) -> 0.011666594
A64: 3190300 | B64: 1070285 | C64: Address 63 | D64: Region 12 | E64: 172865 | F64: 8735 | G64: 0 | H64: 10095 | I64: =F64/$E64 -> 0.050530761 | J64: =G64/$E64 -> 0 | K64: =H64/$E64 -> 0.058398172 | L64: -1193886.2 | M64: 5726509.6 | N64: -1181874.2 | O64: 13651994 | P64: =ABS(L64/M64) -> 0.20848409 | Q64: =ABS(N64/O64) -> 0.086571547
A65: 3193600 | B65: 779616 | C65: Address 64 | D65: Region 2 | E65: 241807 | F65: 26355 | G65: 7615 | H65: 32272 | I65: =F65/$E65 -> 0.10899188 | J65: =G65/$E65 -> 0.031492058 | K65: =H65/$E65 -> 0.13346181 | L65: -3190636.7 | M65: 30062035 | N65: -950546.55 | O65: 44498612 | P65: =ABS(L65/M65) -> 0.10613509 | Q65: =ABS(N65/O65) -> 0.021361263
A66: 3194700 | B66: 1025069 | C66: Address 65 | D66: Region 2 | E66: 262519 | F66: 61628.003 | G66: 13687 | H66: 39725 | I66: =F66/$E66 -> 0.23475635 | J66: =G66/$E66 -> 0.052137179 | K66: =H66/$E66 -> 0.15132238 | L66: -3231754.6 | M66: 46718067 | N66: -685198.52 | O66: 1.038243e+08 | P66: =ABS(L66/M66) -> 0.069175692 | Q66: =ABS(N66/O66) -> 0.0065995969
A67: 3195200 | B67: 1011896 | C67: Address 66 | D67: Region 1 | E67: 412063 | F67: 79478 | G67: 9853 | H67: 87417 | I67: =F67/$E67 -> 0.19287827 | J67: =G67/$E67 -> 0.023911392 | K67: =H67/$E67 -> 0.21214474 | L67: -2332404.7 | M67: 78396546 | N67: -1672258.1 | O67: 1.6212354e+08 | P67: =ABS(L67/M67) -> 0.029751371 | Q67: =ABS(N67/O67) -> 0.010314714
A68: 3196200 | B68: 767279 | C68: Address 67 | D68: Region 1 | E68: 424107 | F68: 82330 | G68: 9115 | H68: 91930 | I68: =F68/$E68 -> 0.19412554 | J68: =G68/$E68 -> 0.021492218 | K68: =H68/$E68 -> 0.21676134 | L68: -2688633 | M68: 75223120 | N68: -2118879.2 | O68: 1.7992181e+08 | P68: =ABS(L68/M68) -> 0.035742109 | Q68: =ABS(N68/O68) -> 0.011776667
A69: 3196600 | B69: 549712 | C69: Address 68 | D69: Region 2 | E69: 300933 | F69: 28596 | G69: 6744 | H69: 30901 | I69: =F69/$E69 -> 0.095024474 | J69: =G69/$E69 -> 0.022410304 | K69: =H69/$E69 -> 0.10268399 | L69: -2992031.7 | M69: 27322442 | N69: -1169248.7 | O69: 27903236 | P69: =ABS(L69/M69) -> 0.10950821 | Q69: =ABS(N69/O69) -> 0.041903694
A70: 3197700 | B70: 859965 | C70: Address 69 | D70: Region 2 | E70: 241283 | F70: 24868 | G70: 6177 | H70: 25730 | I70: =F70/$E70 -> 0.10306569 | J70: =G70/$E70 -> 0.025600643 | K70: =H70/$E70 -> 0.10663826 | L70: -4579684.5 | M70: 23553681 | N70: -3639202.6 | O70: 27443567 | P70: =ABS(L70/M70) -> 0.19443605 | Q70: =ABS(N70/O70) -> 0.13260676
A71: 3199900 | B71: 416348 | C71: Address 70 | D71: Region 1 | E71: 173454 | F71: 12601 | G71: 834 | H71: 17057 | I71: =F71/$E71 -> 0.072647503 | J71: =G71/$E71 -> 0.0048081912 | K71: =H71/$E71 -> 0.098337311 | L71: -1631088.8 | M71: 12790023 | N71: -2341587.7 | O71: 26311377 | P71: =ABS(L71/M71) -> 0.12752821 | Q71: =ABS(N71/O71) -> 0.088995255
A72: 3201000 | B72: 1050300 | C72: Address 71 | D72: Region 1 | E72: 255968 | F72: 18942 | G72: 2446 | H72: 26942 | I72: =F72/$E72 -> 0.074001438 | J72: =G72/$E72 -> 0.009555882 | K72: =H72/$E72 -> 0.10525534 | L72: -1796644.9 | M72: 20598139 | N72: -1206437.3 | O72: 34564965 | P72: =ABS(L72/M72) -> 0.087223649 | Q72: =ABS(N72/O72) -> 0.034903473
A73: 3202100 | B73: 271054 | C73: Address 72 | D73: Region 12 | E73: 122475 | F73: 6182 | G73: 0 | H73: 7711 | I73: =F73/$E73 -> 0.050475607 | J73: =G73/$E73 -> 0 | K73: =H73/$E73 -> 0.062959788 | L73: -934889.22 | M73: 5319872.5 | N73: -843959.3 | O73: 10457335 | P73: =ABS(L73/M73) -> 0.17573527 | Q73: =ABS(N73/O73) -> 0.080705009
A74: 3203200 | B74: 892017 | C74: Address 73 | D74: Region 12 | E74: 68655 | F74: 12153 | G74: 0 | H74: 6756 | I74: =F74/$E74 -> 0.17701551 | J74: =G74/$E74 -> 0 | K74: =H74/$E74 -> 0.098405069 | L74: -598992.11 | M74: 4958444.5 | N74: -748274.28 | O74: 21810644 | P74: =ABS(L74/M74) -> 0.12080242 | Q74: =ABS(N74/O74) -> 0.034307758
...

Sheet Category Averages
A1: Category | B1: Coffee | C1: Sandwich | D1: Hot-Dog | E1: Gastro Waste | F1: Drygoods Waste
A2: {=_xlfn.UNIQUE('Data 2024'!D2:D380)} -> Region 1 | B2: =AVERAGEIFS('Data 2024'!I:I,'Data 2024'!$D:$D,$A2) -> 0.12593511 | C2: =AVERAGEIFS('Data 2024'!J:J,'Data 2024'!$D:$D,$A2) -> 0.0086204905 | D2: =AVERAGEIFS('Data 2024'!K:K,'Data 2024'!$D:$D,$A2) -> 0.12149039 | E2: =AVERAGEIFS('Data 2024'!P:P,'Data 2024'!$D:$D,$A2) -> 0.097515356 | F2: =AVERAGEIFS('Data 2024'!Q:Q,'Data 2024'!$D:$D,$A2) -> 0.061319598
A3: Region 2 | B3: =AVERAGEIFS('Data 2024'!I:I,'Data 2024'!$D:$D,$A3) -> 0.16655609 | C3: =AVERAGEIFS('Data 2024'!J:J,'Data 2024'!$D:$D,$A3) -> 0.033123757 | D3: =AVERAGEIFS('Data 2024'!K:K,'Data 2024'!$D:$D,$A3) -> 0.1465202 | E3: =AVERAGEIFS('Data 2024'!P:P,'Data 2024'!$D:$D,$A3) -> 0.12460792 | F3: =AVERAGEIFS('Data 2024'!Q:Q,'Data 2024'!$D:$D,$A3) -> 0.045521278
A4: Region 12 | B4: =AVERAGEIFS('Data 2024'!I:I,'Data 2024'!$D:$D,$A4) -> 0.073679815 | C4: =AVERAGEIFS('Data 2024'!J:J,'Data 2024'!$D:$D,$A4) -> 0 | D4: =AVERAGEIFS('Data 2024'!K:K,'Data 2024'!$D:$D,$A4) -> 0.045669203 | E4: =AVERAGEIFS('Data 2024'!P:P,'Data 2024'!$D:$D,$A4) -> 0.23299057 | F4: =AVERAGEIFS('Data 2024'!Q:Q,'Data 2024'!$D:$D,$A4) -> 0.06748992

Sheet Segédtábla, Szűrt Adatok
A1: Kútkód | B1: Cím
A2: 11012 | B2: Budapest, Mészáros u. 19. (I.) | C2: {=_xlfn._xlws.SORT(_xlfn.UNIQUE(_xlfn._xlws.FILTER('Data 2024'!C2:C380, ISNUMBER(SEARCH(Riport!#REF!,'Data 2024'!C2:C380)), "Nem elérhető")),,1)} -> Nem elérhető
A3: 11045 | B3: Budapest, Árpád fejedelem út 103. (III.)
A4: 11215 | B4: Budapest, Napfény u. 26. (IX.)
A5: 11311 | B5: Budapest, Istenhegyi u. 45-47. (XII.)
A6: 11399 | B6: Budapest, Róna u. 170. (XIV.)
A7: 11514 | B7: Budapest, Kossuth L. u. 3. (XXI.)
A8: 11761 | B8: Budapest, Pap Károly u. (XIII.)
A9: 11783 | B9: Budapest, Pesti út. 5. (XVII.)
A10: 11800 | B10: Budapest, Borszéki u.
A11: 12063 | B11: Budapest, Vágány u. 21. (XIV.)
A12: 12070 | B12: Budapest, Irinyi u. 45. (XI.)
A13: 12081 | B13: Budapest, Mozaik u.3. (III.)
A14: 12092 | B14: Budapest, Ócsai u. kimenő (XXIII.)
... A380: 45169 | B380: Szabadszállás, Petőfi Sándor út 19.

Sheet Riport
A1: SES Code: | C1: 2506300 | E1: Business Performance Indicator | M1: d
A2: SES Region: | C2: {=Kút_kategóriája} -> Region 2
A3: Partner: | C3: =_xlfn.XLOOKUP(Kútkód,'Data for individual SES'!A:A,'Data for individual SES'!F:F) -> Partner 4
C4: Relative Measures
D7: Quantities | E7: Coffee | F7: Sandwich | G7: Hot-Dog | H7: Gastro Waste | I7: Drygoods Waste
D8: Actual | E8: =_xlfn.XLOOKUP(Kútkód,'Data 2024'!$A2:$A380,'Data 2024'!$I2:$I380) -> 0.11895077 | F8: =_xlfn.XLOOKUP(Kútkód,'Data 2024'!$A2:$A380,'Data 2024'!$J2:$J380) -> 0.022668315 | G8: =_xlfn.XLOOKUP(Kútkód,'Data 2024'!$A2:$A380,'Data 2024'!$K2:$K380) -> 0.11787734 | H8: =_xlfn.XLOOKUP(Kútkód,'Data 2024'!$A2:$A380,'Data 2024'!P2:P380) -> 0.13484369 | I8: =_xlfn.XLOOKUP(Kútkód,'Data 2024'!$A2:$A380,'Data 2024'!Q2:Q380) -> 0.022576637
D9: Category Average | E9: {=AVERAGEIFS('Data 2024'!$I2:$I380,'Data 2024'!$D$2:$D$380,Kút_kategóriája)} -> 0.16655609 | F9: {=AVERAGEIFS('Data 2024'!$J2:$J380,'Data 2024'!$D$2:$D$380,Kút_kategóriája)} -> 0.033123757 | G9: {=AVERAGEIFS('Data 2024'!$K2:$K380,'Data 2024'!$D$2:$D$380,Kút_kategóriája)} -> 0.1465202 | H9: {=AVERAGEIFS('Data 2024'!$P2:$P380,'Data 2024'!$D$2:$D$380,Kút_kategóriája)} -> 0.12460792 | I9: {=AVERAGEIFS('Data 2024'!$Q2:$Q380,'Data 2024'!$D$2:$D$380,Kút_kategóriája)} -> 0.045521278
D10: Actual/Category Average % | E10: =E8/E9 -> 0.71417846 | F10: =F8/F9 -> 0.68435218 | G10: =G8/G9 -> 0.80451256 | H10: =H8/H9 -> 1.0821438 | I10: =I8/I9 -> 0.49595789

Sheet Data for individual SES
A1: SES Code | B1: Kategória | C1: Service Enabling System Address | D1: Regional Manager | E1: Area Manager | F1: Partner Name | G1: Coffee / Category Quotient % | H1: Sandwich / Category Quotient % | I1: Hot-Dog / Category Difference % | J1: Gastro Waste / Category Difference % | K1: Drygoods / Category Difference %
A2: 2476400 | B2: =_xlfn.XLOOKUP(A2,'Data 2024'!A:A,'Data 2024'!D:D) -> Region 1 | C2: SES Address 1 | D2: Regional Manager 1 | E2: Area Manager 1 | F2: Partner 1 | G2: =_xlfn.XLOOKUP($A2,'Data 2024'!$A:$A,'Data 2024'!I:I)/_xlfn.XLOOKUP($B2,'Category Averages'!$A$2:$A$4,'Category Averages'!$B$2:$B$4) -> 0.58523612 | H2: =_xlfn.XLOOKUP($A2,'Data 2024'!$A:$A,'Data 2024'!J:J)/_xlfn.XLOOKUP($B2,'Category Averages'!$A$2:$A$4,'Category Averages'!C$2:C$4) -> 0 | I2: =_xlfn.XLOOKUP($A2,'Data 2024'!$A:$A,'Data 2024'!K:K)/_xlfn.XLOOKUP($B2,'Category Averages'!$A$2:$A$4,'Category Averages'!D$2:D$4) -> 0.80169363 | J2: =_xlfn.XLOOKUP($A2,'Data 2024'!$A:$A,'Data 2024'!P:P)/_xlfn.XLOOKUP($B2,'Category Averages'!$A$2:$A$4,'Category Averages'!E$2:E$4) -> 0.67081789 | K2: =_xlfn.XLOOKUP($A2,'Data 2024'!$A:$A,'Data 2024'!Q:Q)/_xlfn.XLOOKUP($B2,'Category Averages'!$A$2:$A$4,'Category Averages'!F$2:F$4) -> 0.60320768
A3: 2479700 | B3: =_xlfn.XLOOKUP(A3,'Data 2024'!A:A,'Data 2024'!D:D) -> Region 2 | C3: SES Address 2 | D3: Regional Manager 1 | E3: Area Manager 1 | F3: Partner 2 | G3: =_xlfn.XLOOKUP($A3,'Data 2024'!$A:$A,'Data 2024'!I:I)/_xlfn.XLOOKUP($B3,'Category Averages'!$A$2:$A$4,'Category Averages'!$B$2:$B$4) -> 0.39770395 | H3: =_xlfn.XLOOKUP($A3,'Data 2024'!$A:$A,'Data 2024'!J:J)/_xlfn.XLOOKUP($B3,'Category Averages'!$A$2:$A$4,'Category Averages'!C$2:C$4) -> 0.42224032 | I3: =_xlfn.XLOOKUP($A3,'Data 2024'!$A:$A,'Data 2024'!K:K)/_xlfn.XLOOKUP($B3,'Category Averages'!$A$2:$A$4,'Category Averages'!D$2:D$4) -> 0.55217955 | J3: =_xlfn.XLOOKUP($A3,'Data 2024'!$A:$A,'Data 2024'!P:P)/_xlfn.XLOOKUP($B3,'Category Averages'!$A$2:$A$4,'Category Averages'!E$2:E$4) -> 1.6126775 | K3: =_xlfn.XLOOKUP($A3,'Data 2024'!$A:$A,'Data 2024'!Q:Q)/_xlfn.XLOOKUP($B3,'Category Averages'!$A$2:$A$4,'Category Averages'!F$2:F$4) -> 1.2572401
A4: 2496700 | B4: =_xlfn.XLOOKUP(A4,'Data 2024'!A:A,'Data 2024'!D:D) -> Region 1 | C4: SES Address 3 | D4: Regional Manager 1 | E4: Area Manager 3 | F4: Partner 3 | G4: =_xlfn.XLOOKUP($A4,'Data 2024'!$A:$A,'Data 2024'!I:I)/_xlfn.XLOOKUP($B4,'Category Averages'!$A$2:$A$4,'Category Averages'!$B$2:$B$4) -> 0.87903743 | H4: =_xlfn.XLOOKUP($A4,'Data 2024'!$A:$A,'Data 2024'!J:J)/_xlfn.XLOOKUP($B4,'Category Averages'!$A$2:$A$4,'Category Averages'!C$2:C$4) -> 2.0689238 | I4: =_xlfn.XLOOKUP($A4,'Data 2024'!$A:$A,'Data 2024'!K:K)/_xlfn.XLOOKUP($B4,'Category Averages'!$A$2:$A$4,'Category Averages'!D$2:D$4) -> 0.8882162 | J4: =_xlfn.XLOOKUP($A4,'Data 2024'!$A:$A,'Data 2024'!P:P)/_xlfn.XLOOKUP($B4,'Category Averages'!$A$2:$A$4,'Category Averages'!E$2:E$4) -> 0.72566762 | K4: =_xlfn.XLOOKUP($A4,'Data 2024'!$A:$A,'Data 2024'!Q:Q)/_xlfn.XLOOKUP($B4,'Category Averages'!$A$2:$A$4,'Category Averages'!F$2:F$4) -> 0.79510479
A5: 2506300 | B5: =_xlfn.XLOOKUP(A5,'Data 2024'!A:A,'Data 2024'!D:D) -> Region 2 | C5: SES Address 4 | D5: Regional Manager 1 | E5: Area Manager 1 | F5: Partner 4 | G5: =_xlfn.XLOOKUP($A5,'Data 2024'!$A:$A,'Data 2024'!I:I)/_xlfn.XLOOKUP($B5,'Category Averages'!$A$2:$A$4,'Category Averages'!$B$2:$B$4) -> 0.71417846 | H5: =_xlfn.XLOOKUP($A5,'Data 2024'!$A:$A,'Data 2024'!J:J)/_xlfn.XLOOKUP($B5,'Category Averages'!$A$2:$A$4,'Category Averages'!C$2:C$4) -> 0.68435218 | I5: =_xlfn.XLOOKUP($A5,'Data 2024'!$A:$A,'Data 2024'!K:K)/_xlfn.XLOOKUP($B5,'Category Averages'!$A$2:$A$4,'Category Averages'!D$2:D$4) -> 0.80451256 | J5: =_xlfn.XLOOKUP($A5,'Data 2024'!$A:$A,'Data 2024'!P:P)/_xlfn.XLOOKUP($B5,'Category Averages'!$A$2:$A$4,'Category Averages'!E$2:E$4) -> 1.0821438 | K5: =_xlfn.XLOOKUP($A5,'Data 2024'!$A:$A,'Data 2024'!Q:Q)/_xlfn.XLOOKUP($B5,'Category Averages'!$A$2:$A$4,'Category Averages'!F$2:F$4) -> 0.49595789
A6: 2515100 | B6: =_xlfn.XLOOKUP(A6,'Data 2024'!A:A,'Data 2024'!D:D) -> Region 2 | C6: SES Address 5 | D6: Regional Manager 1 | E6: Area Manager 1 | F6: Partner 5 | G6: =_xlfn.XLOOKUP($A6,'Data 2024'!$A:$A,'Data 2024'!I:I)/_xlfn.XLOOKUP($B6,'Category Averages'!$A$2:$A$4,'Category Averages'!$B$2:$B$4) -> 0.74493255 | H6: =_xlfn.XLOOKUP($A6,'Data 2024'!$A:$A,'Data 2024'!J:J)/_xlfn.XLOOKUP($B6,'Category Averages'!$A$2:$A$4,'Category Averages'!C$2:C$4) -> 1.0080492 | I6: =_xlfn.XLOOKUP($A6,'Data 2024'!$A:$A,'Data 2024'!K:K)/_xlfn.XLOOKUP($B6,'Category Averages'!$A$2:$A$4,'Category Averages'!D$2:D$4) -> 0.75819399 | J6: =_xlfn.XLOOKUP($A6,'Data 2024'!$A:$A,'Data 2024'!P:P)/_xlfn.XLOOKUP($B6,'Category Averages'!$A$2:$A$4,'Category Averages'!E$2:E$4) -> 1.0896143 | K6: =_xlfn.XLOOKUP($A6,'Data 2024'!$A:$A,'Data 2024'!Q:Q)/_xlfn.XLOOKUP($B6,'Category Averages'!$A$2:$A$4,'Category Averages'!F$2:F$4) -> 0.71751454
A7: 2526600 | B7: =_xlfn.XLOOKUP(A7,'Data 2024'!A:A,'Data 2024'!D:D) -> Region 1 | C7: SES Address 6 | D7: Regional Manager 1 | E7: Area Manager 6 | F7: Partner 6 | G7: =_xlfn.XLOOKUP($A7,'Data 2024'!$A:$A,'Data 2024'!I:I)/_xlfn.XLOOKUP($B7,'Category Averages'!$A$2:$A$4,'Category Averages'!$B$2:$B$4) -> 0.81929388 | H7: =_xlfn.XLOOKUP($A7,'Data 2024'!$A:$A,'Data 2024'!J:J)/_xlfn.XLOOKUP($B7,'Category Averages'!$A$2:$A$4,'Category Averages'!C$2:C$4) -> 1.3475493 | I7: =_xlfn.XLOOKUP($A7,'Data 2024'!$A:$A,'Data 2024'!K:K)/_xlfn.XLOOKUP($B7,'Category Averages'!$A$2:$A$4,'Category Averages'!D$2:D$4) -> 1.2209776 | J7: =_xlfn.XLOOKUP($A7,'Data 2024'!$A:$A,'Data 2024'!P:P)/_xlfn.XLOOKUP($B7,'Category Averages'!$A$2:$A$4,'Category Averages'!E$2:E$4) -> 1.4715635 | K7: =_xlfn.XLOOKUP($A7,'Data 2024'!$A:$A,'Data 2024'!Q:Q)/_xlfn.XLOOKUP($B7,'Category Averages'!$A$2:$A$4,'Category Averages'!F$2:F$4) -> 2.0838197
A8: 2551300 | B8: =_xlfn.XLOOKUP(A8,'Data 2024'!A:A,'Data 2024'!D:D) -> Region 1 | C8: SES Address 7 | D8: Regional Manager 1 | E8: Area Manager 1 | F8: Partner 5 | G8: =_xlfn.XLOOKUP($A8,'Data 2024'!$A:$A,'Data 2024'!I:I)/_xlfn.XLOOKUP($B8,'Category Averages'!$A$2:$A$4,'Category Averages'!$B$2:$B$4) -> 0.68165046 | H8: =_xlfn.XLOOKUP($A8,'Data 2024'!$A:$A,'Data 2024'!J:J)/_xlfn.XLOOKUP($B8,'Category Averages'!$A$2:$A$4,'Category Averages'!C$2:C$4) -> 1.4953621 | I8: =_xlfn.XLOOKUP($A8,'Data 2024'!$A:$A,'Data 2024'!K:K)/_xlfn.XLOOKUP($B8,'Category Averages'!$A$2:$A$4,'Category Averages'!D$2:D$4) -> 1.069156 | J8: =_xlfn.XLOOKUP($A8,'Data 2024'!$A:$A,'Data 2024'!P:P)/_xlfn.XLOOKUP($B8,'Category Averages'!$A$2:$A$4,'Category Averages'!E$2:E$4) -> 1.150519 | K8: =_xlfn.XLOOKUP($A8,'Data 2024'!$A:$A,'Data 2024'!Q:Q)/_xlfn.XLOOKUP($B8,'Category Averages'!$A$2:$A$4,'Category Averages'!F$2:F$4) -> 1.4593337
A9: 2553500 | B9: =_xlfn.XLOOKUP(A9,'Data 2024'!A:A,'Data 2024'!D:D) -> Region 2 | C9: SES Address 8 | D9: Regional Manager 1 | E9: Area Manager 1 | F9: Partner 8 | G9: =_xlfn.XLOOKUP($A9,'Data 2024'!$A:$A,'Data 2024'!I:I)/_xlfn.XLOOKUP($B9,'Category Averages'!$A$2:$A$4,'Category Averages'!$B$2:$B$4) -> 0.49180404 | H9: =_xlfn.XLOOKUP($A9,'Data 2024'!$A:$A,'Data 2024'!J:J)/_xlfn.XLOOKUP($B9,'Category Averages'!$A$2:$A$4,'Category Averages'!C$2:C$4) -> 0.61315309 | I9: =_xlfn.XLOOKUP($A9,'Data 2024'!$A:$A,'Data 2024'!K:K)/_xlfn.XLOOKUP($B9,'Category Averages'!$A$2:$A$4,'Category Averages'!D$2:D$4) -> 0.79596412 | J9: =_xlfn.XLOOKUP($A9,'Data 2024'!$A:$A,'Data 2024'!P:P)/_xlfn.XLOOKUP($B9,'Category Averages'!$A$2:$A$4,'Category Averages'!E$2:E$4) -> 2.1544613 | K9: =_xlfn.XLOOKUP($A9,'Data 2024'!$A:$A,'Data 2024'!Q:Q)/_xlfn.XLOOKUP($B9,'Category Averages'!$A$2:$A$4,'Category Averages'!F$2:F$4) -> 2.5664315
A10: 2555200 | B10: =_xlfn.XLOOKUP(A10,'Data 2024'!A:A,'Data 2024'!D:D) -> Region 2 | C10: SES Address 9 | D10: Regional Manager 1 | E10: Area Manager 1 | F10: Partner 1 | G10: =_xlfn.XLOOKUP($A10,'Data 2024'!$A:$A,'Data 2024'!I:I)/_xlfn.XLOOKUP($B10,'Category Averages'!$A$2:$A$4,'Category Averages'!$B$2:$B$4) -> 0.63752893 | H10: =_xlfn.XLOOKUP($A10,'Data 2024'!$A:$A,'Data 2024'!J:J)/_xlfn.XLOOKUP($B10,'Category Averages'!$A$2:$A$4,'Category Averages'!C$2:C$4) -> 0.79281541 | I10: =_xlfn.XLOOKUP($A10,'Data 2024'!$A:$A,'Data 2024'!K:K)/_xlfn.XLOOKUP($B10,'Category Averages'!$A$2:$A$4,'Category Averages'!D$2:D$4) -> 0.95108514 | J10: =_xlfn.XLOOKUP($A10,'Data 2024'!$A:$A,'Data 2024'!P:P)/_xlfn.XLOOKUP($B10,'Category Averages'!$A$2:$A$4,'Category Averages'!E$2:E$4) -> 1.2641131 | K10: =_xlfn.XLOOKUP($A10,'Data 2024'!$A:$A,'Data 2024'!Q:Q)/_xlfn.XLOOKUP($B10,'Category Averages'!$A$2:$A$4,'Category Averages'!F$2:F$4) -> 3.3683939
A11: 2581500 | B11: =_xlfn.XLOOKUP(A11,'Data 2024'!A:A,'Data 2024'!D:D) -> Region 2 | C11: SES Address 10 | D11: Regional Manager 1 | E11: Area Manager 6 | F11: Partner 10 | G11: =_xlfn.XLOOKUP($A11,'Data 2024'!$A:$A,'Data 2024'!I:I)/_xlfn.XLOOKUP($B11,'Category Averages'!$A$2:$A$4,'Category Averages'!$B$2:$B$4) -> 0.64406222 | H11: =_xlfn.XLOOKUP($A11,'Data 2024'!$A:$A,'Data 2024'!J:J)/_xlfn.XLOOKUP($B11,'Category Averages'!$A$2:$A$4,'Category Averages'!C$2:C$4) -> 0.6322703 | I11: =_xlfn.XLOOKUP($A11,'Data 2024'!$A:$A,'Data 2024'!K:K)/_xlfn.XLOOKUP($B11,'Category Averages'!$A$2:$A$4,'Category Averages'!D$2:D$4) -> 1.1254496 | J11: =_xlfn.XLOOKUP($A11,'Data 2024'!$A:$A,'Data 2024'!P:P)/_xlfn.XLOOKUP($B11,'Category Averages'!$A$2:$A$4,'Category Averages'!E$2:E$4) -> 0.56468338 | K11: =_xlfn.XLOOKUP($A11,'Data 2024'!$A:$A,'Data 2024'!Q:Q)/_xlfn.XLOOKUP($B11,'Category Averages'!$A$2:$A$4,'Category Averages'!F$2:F$4) -> 0.66935252
A12: 2582200 | B12: =_xlfn.XLOOKUP(A12,'Data 2024'!A:A,'Data 2024'!D:D) -> Region 1 | C12: SES Address 11 | D12: Regional Manager 11 | E12: Area Manager 11 | F12: Partner 11 | G12: =_xlfn.XLOOKUP($A12,'Data 2024'!$A:$A,'Data 2024'!I:I)/_xlfn.XLOOKUP($B12,'Category Averages'!$A$2:$A$4,'Category Averages'!$B$2:$B$4) -> 0.73443709 | H12: =_xlfn.XLOOKUP($A12,'Data 2024'!$A:$A,'Data 2024'!J:J)/_xlfn.XLOOKUP($B12,'Category Averages'!$A$2:$A$4,'Category Averages'!C$2:C$4) -> 2.0352208 | I12: =_xlfn.XLOOKUP($A12,'Data 2024'!$A:$A,'Data 2024'!K:K)/_xlfn.XLOOKUP($B12,'Category Averages'!$A$2:$A$4,'Category Averages'!D$2:D$4) -> 1.2209557 | J12: =_xlfn.XLOOKUP($A12,'Data 2024'!$A:$A,'Data 2024'!P:P)/_xlfn.XLOOKUP($B12,'Category Averages'!$A$2:$A$4,'Category Averages'!E$2:E$4) -> 1.0557613 | K12: =_xlfn.XLOOKUP($A12,'Data 2024'!$A:$A,'Data 2024'!Q:Q)/_xlfn.XLOOKUP($B12,'Category Averages'!$A$2:$A$4,'Category Averages'!F$2:F$4) -> 0.86872596
A13: 2583300 | B13: =_xlfn.XLOOKUP(A13,'Data 2024'!A:A,'Data 2024'!D:D) -> Region 12 | C13: SES Address 12 | D13: Regional Manager 1 | E13: Area Manager 6 | F13: Partner 12 | G13: =_xlfn.XLOOKUP($A13,'Data 2024'!$A:$A,'Data 2024'!I:I)/_xlfn.XLOOKUP($B13,'Category Averages'!$A$2:$A$4,'Category Averages'!$B$2:$B$4) -> 1.5141456 | H13: =_xlfn.XLOOKUP($A13,'Data 2024'!$A:$A,'Data 2024'!J:J)/_xlfn.XLOOKUP($B13,'Category Averages'!$A$2:$A$4,'Category Averages'!C$2:C$4) -> #DIV/0! | I13: =_xlfn.XLOOKUP($A13,'Data 2024'!$A:$A,'Data 2024'!K:K)/_xlfn.XLOOKUP($B13,'Category Averages'!$A$2:$A$4,'Category Averages'!D$2:D$4) -> 0.50562644 | J13: =_xlfn.XLOOKUP($A13,'Data 2024'!$A:$A,'Data 2024'!P:P)/_xlfn.XLOOKUP($B13,'Category Averages'!$A$2:$A$4,'Category Averages'!E$2:E$4) -> 0.16314418 | K13: =_xlfn.XLOOKUP($A13,'Data 2024'!$A:$A,'Data 2024'!Q:Q)/_xlfn.XLOOKUP($B13,'Category Averages'!$A$2:$A$4,'Category Averages'!F$2:F$4) -> 0.31090684
... A382: 5892100 | B382: =_xlfn.XLOOKUP(A382,'Data 2024'!A:A,'Data 2024'!D:D) -> Region 2 | C382: SES Address 381 | D382: Regional Manager 33 | E382: Area Manager 36 | F382: Partner 229 | G382: =_xlfn.XLOOKUP($A382,'Data 2024'!$A:$A,'Data 2024'!I:I)/_xlfn.XLOOKUP($B382,'Category Averages'!$A$2:$A$4,'Category Averages'!$B$2:$B$4) -> 0 | H382: =_xlfn.XLOOKUP($A382,'Data 2024'!$A:$A,'Data 2024'!J:J)/_xlfn.XLOOKUP($B382,'Category Averages'!$A$2:$A$4,'Category Averages'!C$2:C$4) -> 0 | I382: =_xlfn.XLOOKUP($A382,'Data 2024'!$A:$A,'Data 2024'!K:K)/_xlfn.XLOOKUP($B382,'Category Averages'!$A$2:$A$4,'Category Averages'!D$2:D$4) -> 0 | J382: =_xlfn.XLOOKUP($A382,'Data 2024'!$A:$A,'Data 2024'!P:P)/_xlfn.XLOOKUP($B382,'Category Averages'!$A$2:$A$4,'Category Averages'!E$2:E$4) -> 0 | K382: =_xlfn.XLOOKUP($A382,'Data 2024'!$A:$A,'Data 2024'!Q:Q)/_xlfn.XLOOKUP($B382,'Category Averages'!$A$2:$A$4,'Category Averages'!F$2:F$4) -> 0.16913401

Sheet SÉM-Riport
A1: Kútkód: | C1: 467603 | E1: Business Performance Indicator
A2: Kút Kategóriája: | C2: {=Kút_kategóriája} -> #N/A
A3: Állomás neve: | C3: =_xlfn.XLOOKUP(Kútkód,'Data 2024'!B:B,'Data 2024'!C:C) -> #N/A
C4: Fajlagos Mennyiségek
D6: Mennyiségek | E6: Fajlagos Eladott Kávé Darabszám Összes Tranzakcióhoz | F6: Fajlagos Eladott Szendvics Darabszám Összes Tranzakcióhoz | G6: Fajlagos Eladott Hot-Dog Darabszám Összes Tranzakcióhoz | H6: Fajlagos Gasztró Selejt Darabszám Összes Tranzakcióhoz | I6: Fajlagos Szárazáru Selejt Összes Tranzakcióhoz
D7: Tény | E7: =_xlfn.XLOOKUP(Kútkód,'Data 2024'!$B2:$B380,'Data 2024'!$I2:$I380) -> #N/A | F7: =_xlfn.XLOOKUP(Kútkód,'Data 2024'!$B2:$B380,'Data 2024'!$J2:$J380) -> #N/A | G7: =_xlfn.XLOOKUP(Kútkód,'Data 2024'!$B2:$B380,'Data 2024'!$K2:$K380) -> #N/A | H7: =_xlfn.XLOOKUP(Kútkód,'Data 2024'!$B2:$B380,'Data 2024'!P2:P380) -> #N/A | I7: =_xlfn.XLOOKUP(Kútkód,'Data 2024'!$B2:$B380,'Data 2024'!Q2:Q380) -> #N/A
D8: Átlagos Tény Kategóriánként | E8: {=AVERAGEIFS('Data 2024'!$I2:$I380,'Data 2024'!$D$2:$D$380,Kút_kategóriája)} -> #DIV/0! | F8: {=AVERAGEIFS('Data 2024'!$J2:$J380,'Data 2024'!$D$2:$D$380,Kút_kategóriája)} -> #DIV/0! | G8: {=AVERAGEIFS('Data 2024'!$K2:$K380,'Data 2024'!$D$2:$D$380,Kút_kategóriája)} -> #DIV/0! | H8: {=AVERAGEIFS('Data 2024'!$P2:$P380,'Data 2024'!$D$2:$D$380,Kút_kategóriája)} -> #DIV/0! | I8: {=AVERAGEIFS('Data 2024'!$Q2:$Q380,'Data 2024'!$D$2:$D$380,Kút_kategóriája)} -> #DIV/0!
D9: Tény/Átlagos tény arány | E9: =E7/E8 -> #N/A | F9: =F7/F8 -> #N/A | G9: =G7/G8 -> #N/A | H9: =H7/H8 -> #N/A | I9: =I7/I8 -> #N/A
