Workbook

Sheet NEW MODEL BY SES
A1: SERVICE ENABLING SYSTEM CATEGORIZATION MODEL 2024 HUNGARY | C1: Based on a file of slovnaft. | E1: EMPLOYEES | H1: GASTRO | K1: TOTAL NON-FUEL | N1: TOTAL FUEL | Q1: CAR WASH | T1: Points
C2: 1. step | E2: No. of Emp. | F2: No.of SeS | H2: Revenue (Ft) | I2: No. FC FULL | K2: Revenue (Ft) | L2: No.of SeS | N2: Liters | O2: No.of SeS | Q2: Revenue (Ft) | R2: No.of SeS
D3: MAX. | E3: =MAX(E19:E429) -> 28.993577 | F3: =COUNTIF(E$19:E$429,">"&E4) -> 166 | H3: =MAX(H19:H429) -> 2.8219574e+08 | I3: =COUNTIF(H$19:H$429,">"&H4) -> 130 | K3: =MAX(K19:K429) -> 3.341031e+08 | L3: =COUNTIF(K$19:K$429,">"&K4) -> 153 | N3: =MAX(N19:N429) -> 7.4002441e+09 | O3: =COUNTIF(N$19:N$429,">"&N4) -> 194 | Q3: =MAX(Q19:Q429) -> 44622686 | R3: =COUNTIF(Q$19:Q$429,">"&Q4) -> 127 | T3: MAX | U3: =MAX(W19:W429) -> 475
D4: AVG. | E4: =AVERAGE(E19:E429) -> 8.826164 | F4: ô | H4: =AVERAGE(H19:H429) -> 32287064 | I4: ô | K4: =AVERAGE(K19:K429) -> 55060029 | L4: ô | N4: =AVERAGE(N19:N429) -> 1.7091721e+09 | O4: ô | Q4: =AVERAGE(Q19:Q429) -> 4216758.7 | R4: ô | T4: AVERAGE | U4: =AVERAGEIF(W19:W429,">0") -> 182.73723
C5: Set criteria which differentiate SeS' and influence their complexity | D5: MIN. | E5: =MIN(E19:E429) -> 0 | F5: =COUNTIF(E$19:E$429,"<"&E4) -> 245 | H5: =MIN(H19:H429) -> 0 | I5: =COUNTIF(H$19:H$429,"<"&H4) -> 281 | K5: =MIN(K19:K429) -> 0 | L5: =COUNTIF(K$19:K$429,"<"&K4) -> 258 | N5: =MIN(N19:N429) -> 0 | O5: =COUNTIF(N$19:N$429,"<"&N4) -> 217 | Q5: =MIN(Q19:Q429) -> 0 | R5: =COUNTIF(Q$19:Q$429,"<"&Q4) -> 284 | T5: MIN | U5: =SMALL(W19:W429,COUNTIF(W19:W429,0)+1) -> 25.5
C7: 2. step | D7: RANGES | E7: Ranges | F7: No.of SeS | G7: Points | H7: Ranges | I7: No.of SeS | J7: Points | K7: Ranges | L7: No.of SeS | M7: Points | N7: Ranges | O7: No.of SeS | P7: Points | Q7: Ranges | R7: No.of SeS | S7: Points | T7: Values | U7: No.of SeS | V7: Points | W7: CATEGORY | X7: POINTS | Z7: No.of SeS | AA7: %
C8: Set ranges for each criterion and set points for ranges | D8: top 10% of ranking | F8: =COUNTIFS(E$19:E$429,">"&E9) -> 40 | G8: 150 | I8: =COUNTIFS(H$19:H$429,">"&H9) -> 42 | J8: 125 | L8: =COUNTIFS(K$19:K$429,">"&K9) -> 42 | M8: 100 | O8: =COUNTIFS(N$19:N$429,">"&N9) -> 42 | P8: 75 | R8: =COUNTIFS(Q$19:Q$429,">"&Q9) -> 42 | S8: 25 | T8: Has Highway | U8: =COUNTIF(T$19:T$429,T8) -> 34 | V8: 25 | W8: I | X8: > | Y8: =Y9 -> 325 | Z8: =COUNTIFS(W$19:W$429,">"&Y9) -> 46 | AA8: =Z8/$Y$12 -> 0.11192214 | AB8: top 10% of ranking
C9: Only blue numbers are to be changed | D9: next 20% of ranking | E9: {=INDEX(_xlfn._xlws.SORT(E19:E429,,1),TRUNC(COUNT(E19:E429)*(0.9)))} -> 13.451626 | F9: =COUNTIFS(E$19:E$429,">"&E10, E$19:E$429,"<="&E9) -> 81 | G9: 75 | H9: {=INDEX(_xlfn._xlws.SORT(H$19:H$429,,1),COUNT(H$19:H$429)*(0.9))} -> 60403867 | I9: =COUNTIFS(H$19:H$429,">"&H10, H$19:H$429,"<="&H9) -> 82 | J9: 62.5 | K9: {=INDEX(_xlfn._xlws.SORT(K$19:K$429,,1),TRUNC(COUNT(K$19:K$429)*(0.9)))} -> 97091226 | L9: =COUNTIFS(K$19:K$429,">"&K10, K$19:K$429,"<="&K9) -> 82 | M9: 50 | N9: {=INDEX(_xlfn._xlws.SORT(N$19:N$429,,1),TRUNC(COUNT(N$19:N$429)*(0.9)))} -> 2.7618267e+09 | O9: =COUNTIFS(N$19:N$429,">"&N10, N$19:N$429,"<="&N9) -> 82 | P9: 40 | Q9: {=INDEX(_xlfn._xlws.SORT(Q$19:Q$429,,1),TRUNC(COUNT(Q$19:Q$429)*(0.9)))} -> 14839420 | R9: =COUNTIFS(Q$19:Q$429,">"&Q10, Q$19:Q$429,"<="&Q9) -> 82 | S9: 12.5 | T9: No Highway | U9: =COUNTIF(T$19:T$429,T9) -> 377 | V9: 12.5 | W9: II | X9: =Y10&" -" -> 192.5 - | Y9: 325 | Z9: =COUNTIFS(W$19:W$429,">"&Y10, W$19:W$429,"<="&Y9) -> 95 | AA9: =Z9/$Y$12 -> 0.23114355 | AB9: next 20% of ranking
D10: next 35% of ranking | E10: {=INDEX(_xlfn._xlws.SORT(E$19:E$429,,1),TRUNC(COUNT(E$19:E$429)*(0.7)))} -> 9.6974105 | F10: =COUNTIFS(E$19:E$429,">"&E11, E$19:E$429,"<="&E10) -> 146 | G10: 45 | H10: {=INDEX(_xlfn._xlws.SORT(H$19:H$429,,1),COUNT(H$19:H$429)*(0.7))} -> 33023613 | I10: =COUNTIFS(H$19:H$429,">"&H11, H$19:H$429,"<="&H10) -> 144 | J10: 37.5 | K10: {=INDEX(_xlfn._xlws.SORT(K$19:K$429,,1),TRUNC(COUNT(K$19:K$429)*(0.7)))} -> 61459303 | L10: =COUNTIFS(K$19:K$429,">"&K11, K$19:K$429,"<="&K10) -> 144 | M10: 30 | N10: {=INDEX(_xlfn._xlws.SORT(N$19:N$429,,1),TRUNC(COUNT(N$19:N$429)*(0.7)))} -> 2.106685e+09 | O10: =COUNTIFS(N$19:N$429,">"&N11, N$19:N$429,"<="&N10) -> 144 | P10: 22 | Q10: {=INDEX(_xlfn._xlws.SORT(Q$19:Q$429,,1),TRUNC(COUNT(Q$19:Q$429)*(0.7)))} -> 4383858.3 | R10: =COUNTIFS(Q$19:Q$429,">"&Q11, Q$19:Q$429,"<="&Q10) -> 31 | S10: 7.5 | W10: III | X10: =Y11&" -" -> 120.5 - | Y10: 192.5 | Z10: =COUNTIFS(W$19:W$429,">"&Y11, W$19:W$429,"<="&Y10) -> 158 | AA10: =Z10/$Y$12 -> 0.38442822 | AB10: next 40% of ranking
C11: Hints: 1) balance with number of SeS which fall within a range 2) criteria with greater impact on SeS complexity should get more points | D11: bottom 35% of ranking | E11: {=INDEX(_xlfn._xlws.SORT(E$19:E$429,,1),TRUNC(COUNT(E$19:E$429)*(0.35)))} -> 6.506607 | F11: =COUNTIFS(E$19:E$429,">="&E12, E$19:E$429,"<="&E11) -> 144 | G11: 30 | H11: {=INDEX(_xlfn._xlws.SORT(H$19:H$429,,1),COUNT(H$19:H$429)*(0.35))} -> 17219525 | I11: =COUNTIFS(H$19:H$429,">="&H12, H$19:H$429,"<="&H11) -> 143 | J11: 25 | K11: {=INDEX(_xlfn._xlws.SORT(K$19:K$429,,1),TRUNC(COUNT(K$19:K$429)*(0.35)))} -> 37639149 | L11: =COUNTIFS(K$19:K$429,">="&K12, K$19:K$429,"<="&K11) -> 143 | M11: 20 | N11: {=INDEX(_xlfn._xlws.SORT(N$19:N$429,,1),TRUNC(COUNT(N$19:N$429)*(0.35)))} -> 1.3744732e+09 | O11: =COUNTIFS(N$19:N$429,">="&N12, N$19:N$429,"<="&N11) -> 143 | P11: 13 | Q11: {=INDEX(_xlfn._xlws.SORT(Q$19:Q$429,,1),TRUNC(COUNT(Q$19:Q$429)*(0.35)))} -> 0 | R11: =COUNTIFS(Q$19:Q$429,">="&Q12, Q$19:Q$429,"<="&Q11) -> 256 | S11: 5 | W11: IV | X11: ="0 -" -> 0 - | Y11: 120.5 | Z11: =COUNTIFS(W$19:W$429,"<="&Y11) -> 112 | AA11: =Z11/$Y$12 -> 0.27250608 | AB11: bottom 30% of ranking
E12: 0 | H12: 0 | K12: 0 | N12: 0 | Q12: 0 | W12: Total no. of SeS: | Y12: =SUM(Z8:Z11) -> 411 | AA12: =Y12/$Y$12 -> 1
C13: Fill in data for criteria in the table below | D13: Total no. od SeS: | F13: =SUM(F8:F11) -> 411 | I13: =SUM(I8:I11) -> 411 | L13: =SUM(L8:L11) -> 411 | O13: =SUM(O8:O11) -> 411 | R13: =SUM(R8:R11) -> 411 | U13: =SUM(U8:U12) -> 411
E15: EMPLOYEES | H15: GASTRO | K15: TOTAL NON-FUEL | N15: TOTAL FUEL | Q15: CAR WASH | T15: HIGHWAY | W15: 3 | X15: 3 | Y15: 3
W16: 4 | X16: 4 | Y16: 4
A17: Area Manager | B17: Code | C17: Service Enabling System | E17: No. of Employees | F17: No. of Emp. POINTS | H17: GASTRO revenue (Ft) | I17: TOTAL FC POINTS | K17: TOTAL NON-FUEL revenue (Ft) | L17: TOTAL NF POINTS | N17: TOTAL FUEL (Liter) | O17: FUEL POINTS | Q17: CAR WASH revenue (Ft) | R17: CAR WASH POINTS | T17: Highway indicator | U17: CAR WASH POINTS | W17: TOTAL SCORE | X17: NEW CATEGORY (ROMAN) | Y17: NEW CATEGORY (ARABIC)
B18: =B17 -> Code | C18: =C17 -> Service Enabling System | E18: =E17 -> No. of Employees | F18: =F17 -> No. of Emp. POINTS | H18: =H17 -> GASTRO revenue (Ft) | I18: =I17 -> TOTAL FC POINTS | K18: =K17 -> TOTAL NON-FUEL revenue (Ft) | L18: =L17 -> TOTAL NF POINTS | N18: =N17 -> TOTAL FUEL (Liter) | O18: =O17 -> FUEL POINTS | Q18: =Q17 -> CAR WASH revenue (Ft) | R18: =R17 -> CAR WASH POINTS | T18: =T17 -> Highway indicator | U18: =U17 -> CAR WASH POINTS | W18: =W17 -> TOTAL SCORE | X18: =X17 -> NEW CATEGORY (ROMAN) | Y18: =Y17 -> NEW CATEGORY (ARABIC)
A19: Area Manager 1 | B19: 7990200 | C19: Service Enabling System1 | E19: 6.131607 | F19: =IF(E19=0,0,IF(E19<=E$11,G$11,IF(E19<=E$10,G$10,IF(E19<=E$9,G$9,G$8)))) -> 30 | H19: 18387591 | I19: =IF(H19=0,0,IF(H19<=H$11,J$11,IF(H19<=H$10,J$10,IF(H19<=H$9,J$9,J$8)))) -> 37.5 | K19: 42922021 | L19: =IF(K19=0,0,IF(K19<=K$11,M$11,IF(K19<=K$10,M$10,IF(K19<=K$9,M$9,M$8)))) -> 30 | N19: 1.7712494e+09 | O19: =IF(N19=0,0,IF(N19<=N$11,P$11,IF(N19<=N$10,P$10,IF(N19<=N$9,P$9,P$8)))) -> 22 | Q19: 0 | R19: =IF(Q18=0,0,IF(Q18<=Q$11,S$11,IF(Q18<=Q$10,S$10,IF(Q18<=Q$9,S$9,S$8)))) -> 25 | T19: No Highway | U19: =IF(T19=0,0,IF(T19=T$9,V$9,V$8)) -> 12.5 | W19: =F19+I19+L19+O19+R19+U19 -> 157 | X19: =IF(W19<=$Y$11,$W$11,IF(W19<=$Y$10,$W$10,IF(W19<=$Y$9,$W$9,$W$8))) -> III | Y19: =IF(X19="IV",4,IF(X19="III",3,IF(X19="II",2,1))) -> 3
A20: Area Manager 2 | B20: 6172100 | C20: Service Enabling System2 | E20: 6.4649403 | F20: =IF(E20=0,0,IF(E20<=E$11,G$11,IF(E20<=E$10,G$10,IF(E20<=E$9,G$9,G$8)))) -> 30 | H20: 18222206 | I20: =IF(H20=0,0,IF(H20<=H$11,J$11,IF(H20<=H$10,J$10,IF(H20<=H$9,J$9,J$8)))) -> 37.5 | K20: 31859119 | L20: =IF(K20=0,0,IF(K20<=K$11,M$11,IF(K20<=K$10,M$10,IF(K20<=K$9,M$9,M$8)))) -> 20 | N20: 1.6927532e+09 | O20: =IF(N20=0,0,IF(N20<=N$11,P$11,IF(N20<=N$10,P$10,IF(N20<=N$9,P$9,P$8)))) -> 22 | Q20: 0 | R20: =IF(Q19=0,0,IF(Q19<=Q$11,S$11,IF(Q19<=Q$10,S$10,IF(Q19<=Q$9,S$9,S$8)))) -> 0 | T20: No Highway | U20: =IF(T20=0,0,IF(T20=T$9,V$9,V$8)) -> 12.5 | W20: =F20+I20+L20+O20+R20+U20 -> 122 | X20: =IF(W20<=$Y$11,$W$11,IF(W20<=$Y$10,$W$10,IF(W20<=$Y$9,$W$9,$W$8))) -> III | Y20: =IF(X20="IV",4,IF(X20="III",3,IF(X20="II",2,1))) -> 3
A21: Area Manager 3 | B21: 3836200 | C21: Service Enabling System3 | E21: 6.381607 | F21: =IF(E21=0,0,IF(E21<=E$11,G$11,IF(E21<=E$10,G$10,IF(E21<=E$9,G$9,G$8)))) -> 30 | H21: 12939378 | I21: =IF(H21=0,0,IF(H21<=H$11,J$11,IF(H21<=H$10,J$10,IF(H21<=H$9,J$9,J$8)))) -> 25 | K21: 52553933 | L21: =IF(K21=0,0,IF(K21<=K$11,M$11,IF(K21<=K$10,M$10,IF(K21<=K$9,M$9,M$8)))) -> 30 | N21: 1.5375573e+09 | O21: =IF(N21=0,0,IF(N21<=N$11,P$11,IF(N21<=N$10,P$10,IF(N21<=N$9,P$9,P$8)))) -> 22 | Q21: 0 | R21: =IF(Q21=0,0,IF(Q21<=Q$11,S$11,IF(Q21<=Q$10,S$10,IF(Q21<=Q$9,S$9,S$8)))) -> 0 | T21: No Highway | U21: =IF(T21=0,0,IF(T21=T$9,V$9,V$8)) -> 12.5 | W21: =F21+I21+L21+O21+R21+U21 -> 119.5 | X21: =IF(W21<=$Y$11,$W$11,IF(W21<=$Y$10,$W$10,IF(W21<=$Y$9,$W$9,$W$8))) -> IV | Y21: =IF(X21="IV",4,IF(X21="III",3,IF(X21="II",2,1))) -> 4 | AC21: 2
A22: Area Manager 4 | B22: 4287600 | C22: Service Enabling System4 | E22: 6.5695789 | F22: =IF(E22=0,0,IF(E22<=E$11,G$11,IF(E22<=E$10,G$10,IF(E22<=E$9,G$9,G$8)))) -> 45 | H22: 22201509 | I22: =IF(H22=0,0,IF(H22<=H$11,J$11,IF(H22<=H$10,J$10,IF(H22<=H$9,J$9,J$8)))) -> 37.5 | K22: 43323022 | L22: =IF(K22=0,0,IF(K22<=K$11,M$11,IF(K22<=K$10,M$10,IF(K22<=K$9,M$9,M$8)))) -> 30 | N22: 2.0112564e+09 | O22: =IF(N22=0,0,IF(N22<=N$11,P$11,IF(N22<=N$10,P$10,IF(N22<=N$9,P$9,P$8)))) -> 22 | Q22: 11171200 | R22: =IF(Q22=0,0,IF(Q22<=Q$11,S$11,IF(Q22<=Q$10,S$10,IF(Q22<=Q$9,S$9,S$8)))) -> 12.5 | T22: No Highway | U22: =IF(T22=0,0,IF(T22=T$9,V$9,V$8)) -> 12.5 | W22: =F22+I22+L22+O22+R22+U22 -> 159.5 | X22: =IF(W22<=$Y$11,$W$11,IF(W22<=$Y$10,$W$10,IF(W22<=$Y$9,$W$9,$W$8))) -> III | Y22: =IF(X22="IV",4,IF(X22="III",3,IF(X22="II",2,1))) -> 3 | AC22: 3
A23: Area Manager 5 | B23: 3559900 | C23: Service Enabling System5 | E23: 6.8195789 | F23: =IF(E23=0,0,IF(E23<=E$11,G$11,IF(E23<=E$10,G$10,IF(E23<=E$9,G$9,G$8)))) -> 45 | H23: 16463433 | I23: =IF(H23=0,0,IF(H23<=H$11,J$11,IF(H23<=H$10,J$10,IF(H23<=H$9,J$9,J$8)))) -> 25 | K23: 46730954 | L23: =IF(K23=0,0,IF(K23<=K$11,M$11,IF(K23<=K$10,M$10,IF(K23<=K$9,M$9,M$8)))) -> 30 | N23: 1.5607576e+09 | O23: =IF(N23=0,0,IF(N23<=N$11,P$11,IF(N23<=N$10,P$10,IF(N23<=N$9,P$9,P$8)))) -> 22 | Q23: 0 | R23: =IF(Q23=0,0,IF(Q23<=Q$11,S$11,IF(Q23<=Q$10,S$10,IF(Q23<=Q$9,S$9,S$8)))) -> 0 | T23: No Highway | U23: =IF(T23=0,0,IF(T23=T$9,V$9,V$8)) -> 12.5 | W23: =F23+I23+L23+O23+R23+U23 -> 134.5 | X23: =IF(W23<=$Y$11,$W$11,IF(W23<=$Y$10,$W$10,IF(W23<=$Y$9,$W$9,$W$8))) -> III | Y23: =IF(X23="IV",4,IF(X23="III",3,IF(X23="II",2,1))) -> 3 | AC23: 4
A24: Area Manager 6 | B24: 6246600 | C24: Service Enabling System6 | E24: 6.2982736 | F24: =IF(E24=0,0,IF(E24<=E$11,G$11,IF(E24<=E$10,G$10,IF(E24<=E$9,G$9,G$8)))) -> 30 | H24: 11475939 | I24: =IF(H24=0,0,IF(H24<=H$11,J$11,IF(H24<=H$10,J$10,IF(H24<=H$9,J$9,J$8)))) -> 25 | K24: 35211972 | L24: =IF(K24=0,0,IF(K24<=K$11,M$11,IF(K24<=K$10,M$10,IF(K24<=K$9,M$9,M$8)))) -> 20 | N24: 9.9808875e+08 | O24: =IF(N24=0,0,IF(N24<=N$11,P$11,IF(N24<=N$10,P$10,IF(N24<=N$9,P$9,P$8)))) -> 13 | Q24: 0 | R24: =IF(Q24=0,0,IF(Q24<=Q$11,S$11,IF(Q24<=Q$10,S$10,IF(Q24<=Q$9,S$9,S$8)))) -> 0 | T24: No Highway | U24: =IF(T24=0,0,IF(T24=T$9,V$9,V$8)) -> 12.5 | W24: =F24+I24+L24+O24+R24+U24 -> 100.5 | X24: =IF(W24<=$Y$11,$W$11,IF(W24<=$Y$10,$W$10,IF(W24<=$Y$9,$W$9,$W$8))) -> IV | Y24: =IF(X24="IV",4,IF(X24="III",3,IF(X24="II",2,1))) -> 4
A25: Area Manager 4 | B25: 4237400 | C25: Service Enabling System7 | E25: 5.5056631 | F25: =IF(E25=0,0,IF(E25<=E$11,G$11,IF(E25<=E$10,G$10,IF(E25<=E$9,G$9,G$8)))) -> 30 | H25: 22563282 | I25: =IF(H25=0,0,IF(H25<=H$11,J$11,IF(H25<=H$10,J$10,IF(H25<=H$9,J$9,J$8)))) -> 37.5 | K25: 49200236 | L25: =IF(K25=0,0,IF(K25<=K$11,M$11,IF(K25<=K$10,M$10,IF(K25<=K$9,M$9,M$8)))) -> 30 | N25: 7.122357e+08 | O25: =IF(N25=0,0,IF(N25<=N$11,P$11,IF(N25<=N$10,P$10,IF(N25<=N$9,P$9,P$8)))) -> 13 | Q25: 0 | R25: =IF(Q25=0,0,IF(Q25<=Q$11,S$11,IF(Q25<=Q$10,S$10,IF(Q25<=Q$9,S$9,S$8)))) -> 0 | T25: No Highway | U25: =IF(T25=0,0,IF(T25=T$9,V$9,V$8)) -> 12.5 | W25: =F25+I25+L25+O25+R25+U25 -> 123 | X25: =IF(W25<=$Y$11,$W$11,IF(W25<=$Y$10,$W$10,IF(W25<=$Y$9,$W$9,$W$8))) -> III | Y25: =IF(X25="IV",4,IF(X25="III",3,IF(X25="II",2,1))) -> 3
A26: Area Manager 6 | B26: 7870200 | C26: Service Enabling System8 | E26: 10.135382 | F26: =IF(E26=0,0,IF(E26<=E$11,G$11,IF(E26<=E$10,G$10,IF(E26<=E$9,G$9,G$8)))) -> 75 | H26: 35321225 | I26: =IF(H26=0,0,IF(H26<=H$11,J$11,IF(H26<=H$10,J$10,IF(H26<=H$9,J$9,J$8)))) -> 62.5 | K26: 47914999 | L26: =IF(K26=0,0,IF(K26<=K$11,M$11,IF(K26<=K$10,M$10,IF(K26<=K$9,M$9,M$8)))) -> 30 | N26: 2.1130297e+09 | O26: =IF(N26=0,0,IF(N26<=N$11,P$11,IF(N26<=N$10,P$10,IF(N26<=N$9,P$9,P$8)))) -> 40 | Q26: 7176299.2 | R26: =IF(Q26=0,0,IF(Q26<=Q$11,S$11,IF(Q26<=Q$10,S$10,IF(Q26<=Q$9,S$9,S$8)))) -> 12.5 | T26: No Highway | U26: =IF(T26=0,0,IF(T26=T$9,V$9,V$8)) -> 12.5 | W26: =F26+I26+L26+O26+R26+U26 -> 232.5 | X26: =IF(W26<=$Y$11,$W$11,IF(W26<=$Y$10,$W$10,IF(W26<=$Y$9,$W$9,$W$8))) -> II | Y26: =IF(X26="IV",4,IF(X26="III",3,IF(X26="II",2,1))) -> 2
A27: Area Manager 4 | B27: 4238500 | C27: Service Enabling System9 | E27: 10.135382 | F27: =IF(E27=0,0,IF(E27<=E$11,G$11,IF(E27<=E$10,G$10,IF(E27<=E$9,G$9,G$8)))) -> 75 | H27: 65285859 | I27: =IF(H27=0,0,IF(H27<=H$11,J$11,IF(H27<=H$10,J$10,IF(H27<=H$9,J$9,J$8)))) -> 125 | K27: 67991186 | L27: =IF(K27=0,0,IF(K27<=K$11,M$11,IF(K27<=K$10,M$10,IF(K27<=K$9,M$9,M$8)))) -> 50 | N27: 1.4758418e+09 | O27: =IF(N27=0,0,IF(N27<=N$11,P$11,IF(N27<=N$10,P$10,IF(N27<=N$9,P$9,P$8)))) -> 22 | Q27: 0 | R27: =IF(Q27=0,0,IF(Q27<=Q$11,S$11,IF(Q27<=Q$10,S$10,IF(Q27<=Q$9,S$9,S$8)))) -> 0 | T27: No Highway | U27: =IF(T27=0,0,IF(T27=T$9,V$9,V$8)) -> 12.5 | W27: =F27+I27+L27+O27+R27+U27 -> 284.5 | X27: =IF(W27<=$Y$11,$W$11,IF(W27<=$Y$10,$W$10,IF(W27<=$Y$9,$W$9,$W$8))) -> II | Y27: =IF(X27="IV",4,IF(X27="III",3,IF(X27="II",2,1))) -> 2
A28: Area Manager 7 | B28: 7337100 | C28: Service Enabling System10 | E28: 6.6161 | F28: =IF(E28=0,0,IF(E28<=E$11,G$11,IF(E28<=E$10,G$10,IF(E28<=E$9,G$9,G$8)))) -> 45 | H28: 13387366 | I28: =IF(H28=0,0,IF(H28<=H$11,J$11,IF(H28<=H$10,J$10,IF(H28<=H$9,J$9,J$8)))) -> 25 | K28: 38703113 | L28: =IF(K28=0,0,IF(K28<=K$11,M$11,IF(K28<=K$10,M$10,IF(K28<=K$9,M$9,M$8)))) -> 30 | N28: 1.5683303e+09 | O28: =IF(N28=0,0,IF(N28<=N$11,P$11,IF(N28<=N$10,P$10,IF(N28<=N$9,P$9,P$8)))) -> 22 | Q28: 0 | R28: =IF(Q28=0,0,IF(Q28<=Q$11,S$11,IF(Q28<=Q$10,S$10,IF(Q28<=Q$9,S$9,S$8)))) -> 0 | T28: No Highway | U28: =IF(T28=0,0,IF(T28=T$9,V$9,V$8)) -> 12.5 | W28: =F28+I28+L28+O28+R28+U28 -> 134.5 | X28: =IF(W28<=$Y$11,$W$11,IF(W28<=$Y$10,$W$10,IF(W28<=$Y$9,$W$9,$W$8))) -> III | Y28: =IF(X28="IV",4,IF(X28="III",3,IF(X28="II",2,1))) -> 3
A29: Area Manager 8 | B29: 3545900 | C29: Service Enabling System11 | E29: 13.451626 | F29: =IF(E29=0,0,IF(E29<=E$11,G$11,IF(E29<=E$10,G$10,IF(E29<=E$9,G$9,G$8)))) -> 75 | H29: 23668642 | I29: =IF(H29=0,0,IF(H29<=H$11,J$11,IF(H29<=H$10,J$10,IF(H29<=H$9,J$9,J$8)))) -> 37.5 | K29: 58848501 | L29: =IF(K29=0,0,IF(K29<=K$11,M$11,IF(K29<=K$10,M$10,IF(K29<=K$9,M$9,M$8)))) -> 30 | N29: 2.1700502e+09 | O29: =IF(N29=0,0,IF(N29<=N$11,P$11,IF(N29<=N$10,P$10,IF(N29<=N$9,P$9,P$8)))) -> 40 | Q29: 1252148.1 | R29: =IF(Q29=0,0,IF(Q29<=Q$11,S$11,IF(Q29<=Q$10,S$10,IF(Q29<=Q$9,S$9,S$8)))) -> 7.5 | T29: No Highway | U29: =IF(T29=0,0,IF(T29=T$9,V$9,V$8)) -> 12.5 | W29: =F29+I29+L29+O29+R29+U29 -> 202.5 | X29: =IF(W29<=$Y$11,$W$11,IF(W29<=$Y$10,$W$10,IF(W29<=$Y$9,$W$9,$W$8))) -> II | Y29: =IF(X29="IV",4,IF(X29="III",3,IF(X29="II",2,1))) -> 2
A30: Area Manager 9 | B30: 4242900 | C30: Service Enabling System12 | E30: 10.135382 | F30: =IF(E30=0,0,IF(E30<=E$11,G$11,IF(E30<=E$10,G$10,IF(E30<=E$9,G$9,G$8)))) -> 75 | H30: 70170988 | I30: =IF(H30=0,0,IF(H30<=H$11,J$11,IF(H30<=H$10,J$10,IF(H30<=H$9,J$9,J$8)))) -> 125 | K30: 1.1361453e+08 | L30: =IF(K30=0,0,IF(K30<=K$11,M$11,IF(K30<=K$10,M$10,IF(K30<=K$9,M$9,M$8)))) -> 100 | N30: 2.3163671e+09 | O30: =IF(N30=0,0,IF(N30<=N$11,P$11,IF(N30<=N$10,P$10,IF(N30<=N$9,P$9,P$8)))) -> 40 | Q30: 0 | R30: =IF(Q30=0,0,IF(Q30<=Q$11,S$11,IF(Q30<=Q$10,S$10,IF(Q30<=Q$9,S$9,S$8)))) -> 0 | T30: No Highway | U30: =IF(T30=0,0,IF(T30=T$9,V$9,V$8)) -> 12.5 | W30: =F30+I30+L30+O30+R30+U30 -> 352.5 | X30: =IF(W30<=$Y$11,$W$11,IF(W30<=$Y$10,$W$10,IF(W30<=$Y$9,$W$9,$W$8))) -> I | Y30: =IF(X30="IV",4,IF(X30="III",3,IF(X30="II",2,1))) -> 1
A31: Area Manager 9 | B31: 4268400 | C31: Service Enabling System13 | E31: 5.693635 | F31: =IF(E31=0,0,IF(E31<=E$11,G$11,IF(E31<=E$10,G$10,IF(E31<=E$9,G$9,G$8)))) -> 30 | H31: 28798256 | I31: =IF(H31=0,0,IF(H31<=H$11,J$11,IF(H31<=H$10,J$10,IF(H31<=H$9,J$9,J$8)))) -> 37.5 | K31: 79342868 | L31: =IF(K31=0,0,IF(K31<=K$11,M$11,IF(K31<=K$10,M$10,IF(K31<=K$9,M$9,M$8)))) -> 50 | N31: 1.8632632e+09 | O31: =IF(N31=0,0,IF(N31<=N$11,P$11,IF(N31<=N$10,P$10,IF(N31<=N$9,P$9,P$8)))) -> 22 | Q31: 0 | R31: =IF(Q31=0,0,IF(Q31<=Q$11,S$11,IF(Q31<=Q$10,S$10,IF(Q31<=Q$9,S$9,S$8)))) -> 0 | T31: No Highway | U31: =IF(T31=0,0,IF(T31=T$9,V$9,V$8)) -> 12.5 | W31: =F31+I31+L31+O31+R31+U31 -> 152 | X31: =IF(W31<=$Y$11,$W$11,IF(W31<=$Y$10,$W$10,IF(W31<=$Y$9,$W$9,$W$8))) -> III | Y31: =IF(X31="IV",4,IF(X31="III",3,IF(X31="II",2,1))) -> 3
A32: Area Manager 4 | B32: 8245200 | C32: Service Enabling System14 | E32: 5.5056631 | F32: =IF(E32=0,0,IF(E32<=E$11,G$11,IF(E32<=E$10,G$10,IF(E32<=E$9,G$9,G$8)))) -> 30 | H32: 28219862 | I32: =IF(H32=0,0,IF(H32<=H$11,J$11,IF(H32<=H$10,J$10,IF(H32<=H$9,J$9,J$8)))) -> 37.5 | K32: 44122399 | L32: =IF(K32=0,0,IF(K32<=K$11,M$11,IF(K32<=K$10,M$10,IF(K32<=K$9,M$9,M$8)))) -> 30 | N32: 7.938546e+08 | O32: =IF(N32=0,0,IF(N32<=N$11,P$11,IF(N32<=N$10,P$10,IF(N32<=N$9,P$9,P$8)))) -> 13 | Q32: 0 | R32: =IF(Q32=0,0,IF(Q32<=Q$11,S$11,IF(Q32<=Q$10,S$10,IF(Q32<=Q$9,S$9,S$8)))) -> 0 | T32: No Highway | U32: =IF(T32=0,0,IF(T32=T$9,V$9,V$8)) -> 12.5 | W32: =F32+I32+L32+O32+R32+U32 -> 123 | X32: =IF(W32<=$Y$11,$W$11,IF(W32<=$Y$10,$W$10,IF(W32<=$Y$9,$W$9,$W$8))) -> III | Y32: =IF(X32="IV",4,IF(X32="III",3,IF(X32="II",2,1))) -> 3
A33: Area Manager 4 | B33: 5065400 | C33: Service Enabling System15 | E33: 6.131607 | F33: =IF(E33=0,0,IF(E33<=E$11,G$11,IF(E33<=E$10,G$10,IF(E33<=E$9,G$9,G$8)))) -> 30 | H33: 26977481 | I33: =IF(H33=0,0,IF(H33<=H$11,J$11,IF(H33<=H$10,J$10,IF(H33<=H$9,J$9,J$8)))) -> 37.5 | K33: 69619586 | L33: =IF(K33=0,0,IF(K33<=K$11,M$11,IF(K33<=K$10,M$10,IF(K33<=K$9,M$9,M$8)))) -> 50 | N33: 1.813463e+09 | O33: =IF(N33=0,0,IF(N33<=N$11,P$11,IF(N33<=N$10,P$10,IF(N33<=N$9,P$9,P$8)))) -> 22 | Q33: 0 | R33: =IF(Q33=0,0,IF(Q33<=Q$11,S$11,IF(Q33<=Q$10,S$10,IF(Q33<=Q$9,S$9,S$8)))) -> 0 | T33: No Highway | U33: =IF(T33=0,0,IF(T33=T$9,V$9,V$8)) -> 12.5 | W33: =F33+I33+L33+O33+R33+U33 -> 152 | X33: =IF(W33<=$Y$11,$W$11,IF(W33<=$Y$10,$W$10,IF(W33<=$Y$9,$W$9,$W$8))) -> III | Y33: =IF(X33="IV",4,IF(X33="III",3,IF(X33="II",2,1))) -> 3
A34: Area Manager 1 | B34: 4240700 | C34: Service Enabling System16 | E34: 10.135382 | F34: =IF(E34=0,0,IF(E34<=E$11,G$11,IF(E34<=E$10,G$10,IF(E34<=E$9,G$9,G$8)))) -> 75 | H34: 55495457 | I34: =IF(H34=0,0,IF(H34<=H$11,J$11,IF(H34<=H$10,J$10,IF(H34<=H$9,J$9,J$8)))) -> 62.5 | K34: 94431896 | L34: =IF(K34=0,0,IF(K34<=K$11,M$11,IF(K34<=K$10,M$10,IF(K34<=K$9,M$9,M$8)))) -> 50 | N34: 2.2825791e+09 | O34: =IF(N34=0,0,IF(N34<=N$11,P$11,IF(N34<=N$10,P$10,IF(N34<=N$9,P$9,P$8)))) -> 40 | Q34: 11308544 | R34: =IF(Q34=0,0,IF(Q34<=Q$11,S$11,IF(Q34<=Q$10,S$10,IF(Q34<=Q$9,S$9,S$8)))) -> 12.5 | T34: No Highway | U34: =IF(T34=0,0,IF(T34=T$9,V$9,V$8)) -> 12.5 | W34: =F34+I34+L34+O34+R34+U34 -> 252.5 | X34: =IF(W34<=$Y$11,$W$11,IF(W34<=$Y$10,$W$10,IF(W34<=$Y$9,$W$9,$W$8))) -> II | Y34: =IF(X34="IV",4,IF(X34="III",3,IF(X34="II",2,1))) -> 2
A35: Area Manager 4 | B35: 5039200 | C35: Service Enabling System17 | E35: 16.041951 | F35: =IF(E35=0,0,IF(E35<=E$11,G$11,IF(E35<=E$10,G$10,IF(E35<=E$9,G$9,G$8)))) -> 150 | H35: 96400527 | I35: =IF(H35=0,0,IF(H35<=H$11,J$11,IF(H35<=H$10,J$10,IF(H35<=H$9,J$9,J$8)))) -> 125 | K35: 1.7288181e+08 | L35: =IF(K35=0,0,IF(K35<=K$11,M$11,IF(K35<=K$10,M$10,IF(K35<=K$9,M$9,M$8)))) -> 100 | N35: 2.1430985e+09 | O35: =IF(N35=0,0,IF(N35<=N$11,P$11,IF(N35<=N$10,P$10,IF(N35<=N$9,P$9,P$8)))) -> 40 | Q35: 0 | R35: =IF(Q35=0,0,IF(Q35<=Q$11,S$11,IF(Q35<=Q$10,S$10,IF(Q35<=Q$9,S$9,S$8)))) -> 0 | T35: Has Highway | U35: =IF(T35=0,0,IF(T35=T$9,V$9,V$8)) -> 25 | W35: =F35+I35+L35+O35+R35+U35 -> 440 | X35: =IF(W35<=$Y$11,$W$11,IF(W35<=$Y$10,$W$10,IF(W35<=$Y$9,$W$9,$W$8))) -> I | Y35: =IF(X35="IV",4,IF(X35="III",3,IF(X35="II",2,1))) -> 1
... A429: Area Manager 4 | B429: 4267300 | C429: Service Enabling System411 | E429: 6.131607 | F429: =IF(E429=0,0,IF(E429<=E$11,G$11,IF(E429<=E$10,G$10,IF(E429<=E$9,G$9,G$8)))) -> 30 | H429: 32659717 | I429: =IF(H429=0,0,IF(H429<=H$11,J$11,IF(H429<=H$10,J$10,IF(H429<=H$9,J$9,J$8)))) -> 37.5 | K429: 59087598 | L429: =IF(K429=0,0,IF(K429<=K$11,M$11,IF(K429<=K$10,M$10,IF(K429<=K$9,M$9,M$8)))) -> 30 | N429: 1.9602402e+09 | O429: =IF(N429=0,0,IF(N429<=N$11,P$11,IF(N429<=N$10,P$10,IF(N429<=N$9,P$9,P$8)))) -> 22 | Q429: 0 | R429: =IF(Q429=0,0,IF(Q429<=Q$11,S$11,IF(Q429<=Q$10,S$10,IF(Q429<=Q$9,S$9,S$8)))) -> 0 | T429: No Highway | U429: =IF(T429=0,0,IF(T429=T$9,V$9,V$8)) -> 12.5 | W429: =F429+I429+L429+O429+R429+U429 -> 132 | X429: =IF(W429<=$Y$11,$W$11,IF(W429<=$Y$10,$W$10,IF(W429<=$Y$9,$W$9,$W$8))) -> III | Y429: =IF(X429="IV",4,IF(X429="III",3,IF(X429="II",2,1))) -> 3

Sheet calcuation
A1: EMPLOYEES | E1: TOTAL FUEL | I1: LPG | M1: TOTAL NON-FUEL | Q1: GASTRO | U1: CAR WASH | Y1: Total
A2: Code | B2: GASTRO revenue (EUR) | C2: d | E2: Code | F2: GASTRO revenue (EUR) | G2: d | I2: d | J2: d | K2: d | M2: d | N2: d | O2: d | Q2: d | R2: d | S2: d | U2: d | V2: d | W2: d | Y2: d | Z2: d | AA2: d
A3: 10748 | B3: 34.48 | C3: =PERCENTRANK($B$3:$B$241,B3) -> 1 | E3: 10612 | F3: 9320662.4 | G3: =PERCENTRANK($F$3:$F$241,F3) -> 1 | I3: 10106 | J3: 522419.41 | K3: =PERCENTRANK($J$3:$J$118,J3) -> 1 | M3: 10748 | N3: 3036978.2 | O3: =PERCENTRANK($N$3:$N$241,N3) -> 1 | Q3: 10748 | R3: 1385751.1 | S3: =PERCENTRANK($R$3:$R$241,R3) -> 1 | U3: 20401 | V3: 81496.34 | W3: =PERCENTRANK($V$3:$V$184,V3) -> 1 | Y3: 10106 | Z3: 482.5 | AA3: =PERCENTRANK($Z$3:$Z$241,Z3) -> 1
A4: 40144 | B4: 26.76 | C4: =PERCENTRANK($B$3:$B$241,B4) -> 0.995 | E4: 10611 | F4: 7483728.3 | G4: =PERCENTRANK($F$3:$F$241,F4) -> 0.995 | I4: 10124 | J4: 473992.41 | K4: =PERCENTRANK($J$3:$J$118,J4) -> 0.991 | M4: 10612 | N4: 2588735.5 | O4: =PERCENTRANK($N$3:$N$241,N4) -> 0.995 | Q4: 11412 | R4: 1025325.2 | S4: =PERCENTRANK($R$3:$R$241,R4) -> 0.995 | U4: 20519 | V4: 70870.22 | W4: =PERCENTRANK($V$3:$V$184,V4) -> 0.994 | Y4: 11420 | Z4: 475 | AA4: =PERCENTRANK($Z$3:$Z$241,Z4) -> 0.995
A5: 40145 | B5: 26.07 | C5: =PERCENTRANK($B$3:$B$241,B5) -> 0.991 | E5: 10748 | F5: 7396433.9 | G5: =PERCENTRANK($F$3:$F$241,F5) -> 0.991 | I5: 30602 | J5: 376425.44 | K5: =PERCENTRANK($J$3:$J$118,J5) -> 0.982 | M5: 11412 | N5: 2431440.9 | O5: =PERCENTRANK($N$3:$N$241,N5) -> 0.991 | Q5: 30418 | R5: 726701.71 | S5: =PERCENTRANK($R$3:$R$241,R5) -> 0.991 | U5: 11803 | V5: 65474.52 | W5: =PERCENTRANK($V$3:$V$184,V5) -> 0.988 | Y5: 10105 | Z5: 462.5 | AA5: =PERCENTRANK($Z$3:$Z$241,Z5) -> 0.987
A6: 11412 | B6: 25.69 | C6: =PERCENTRANK($B$3:$B$241,B6) -> 0.987 | E6: 11906 | F6: 6933824.9 | G6: =PERCENTRANK($F$3:$F$241,F6) -> 0.987 | I6: 11906 | J6: 373292.52 | K6: =PERCENTRANK($J$3:$J$118,J6) -> 0.973 | M6: 10105 | N6: 2119676 | O6: =PERCENTRANK($N$3:$N$241,N6) -> 0.987 | Q6: 40144 | R6: 668748.97 | S6: =PERCENTRANK($R$3:$R$241,R6) -> 0.987 | U6: 10101 | V6: 61525.31 | W6: =PERCENTRANK($V$3:$V$184,V6) -> 0.983 | Y6: 10748 | Z6: 462.5 | AA6: =PERCENTRANK($Z$3:$Z$241,Z6) -> 0.987
A7: 40206 | B7: 25.09 | C7: =PERCENTRANK($B$3:$B$241,B7) -> 0.983 | E7: 20404 | F7: 6398878.2 | G7: =PERCENTRANK($F$3:$F$241,F7) -> 0.983 | I7: 10103 | J7: 303144.44 | K7: =PERCENTRANK($J$3:$J$118,J7) -> 0.965 | M7: 30418 | N7: 1890209.1 | O7: =PERCENTRANK($N$3:$N$241,N7) -> 0.983 | Q7: 30608 | R7: 660580.67 | S7: =PERCENTRANK($R$3:$R$241,R7) -> 0.983 | U7: 10124 | V7: 60843.28 | W7: =PERCENTRANK($V$3:$V$184,V7) -> 0.977 | Y7: 30608 | Z7: 457.5 | AA7: =PERCENTRANK($Z$3:$Z$241,Z7) -> 0.983
A8: 10612 | B8: 21.9 | C8: =PERCENTRANK($B$3:$B$241,B8) -> 0.978 | E8: 11706 | F8: 6125738.3 | G8: =PERCENTRANK($F$3:$F$241,F8) -> 0.978 | I8: 40212 | J8: 296474.04 | K8: =PERCENTRANK($J$3:$J$118,J8) -> 0.956 | M8: 30608 | N8: 1778932.5 | O8: =PERCENTRANK($N$3:$N$241,N8) -> 0.978 | Q8: 10612 | R8: 584663.09 | S8: =PERCENTRANK($R$3:$R$241,R8) -> 0.978 | U8: 10737 | V8: 60234.79 | W8: =PERCENTRANK($V$3:$V$184,V8) -> 0.972 | Y8: 11412 | Z8: 455 | AA8: =PERCENTRANK($Z$3:$Z$241,Z8) -> 0.978
A9: 20216 | B9: 20.08 | C9: =PERCENTRANK($B$3:$B$241,B9) -> 0.974 | E9: 10105 | F9: 6003290.4 | G9: =PERCENTRANK($F$3:$F$241,F9) -> 0.974 | I9: 20520 | J9: 295361.28 | K9: =PERCENTRANK($J$3:$J$118,J9) -> 0.947 | M9: 10611 | N9: 1693369.5 | O9: =PERCENTRANK($N$3:$N$241,N9) -> 0.974 | Q9: 40131 | R9: 569548.58 | S9: =PERCENTRANK($R$3:$R$241,R9) -> 0.974 | U9: 40139 | V9: 59334.92 | W9: =PERCENTRANK($V$3:$V$184,V9) -> 0.966 | Y9: 10611 | Z9: 450 | AA9: =PERCENTRANK($Z$3:$Z$241,Z9) -> 0.97
A10: 10611 | B10: 19.13 | C10: =PERCENTRANK($B$3:$B$241,B10) -> 0.97 | E10: 11211 | F10: 5986867.2 | G10: =PERCENTRANK($F$3:$F$241,F10) -> 0.97 | I10: 20435 | J10: 280655.84 | K10: =PERCENTRANK($J$3:$J$118,J10) -> 0.939 | M10: 40144 | N10: 1618942.9 | O10: =PERCENTRANK($N$3:$N$241,N10) -> 0.97 | Q10: 40206 | R10: 549693.46 | S10: =PERCENTRANK($R$3:$R$241,R10) -> 0.97 | U10: 40109 | V10: 58707.57 | W10: =PERCENTRANK($V$3:$V$184,V10) -> 0.961 | Y10: 10612 | Z10: 450 | AA10: =PERCENTRANK($Z$3:$Z$241,Z10) -> 0.97
A11: 11501 | B11: 16.49 | C11: =PERCENTRANK($B$3:$B$241,B11) -> 0.966 | E11: 11420 | F11: 5861059.8 | G11: =PERCENTRANK($F$3:$F$241,F11) -> 0.966 | I11: 11420 | J11: 279314.44 | K11: =PERCENTRANK($J$3:$J$118,J11) -> 0.93 | M11: 40131 | N11: 1579016.1 | O11: =PERCENTRANK($N$3:$N$241,N11) -> 0.966 | Q11: 20216 | R11: 529071.79 | S11: =PERCENTRANK($R$3:$R$241,R11) -> 0.966 | U11: 40123 | V11: 58551.21 | W11: =PERCENTRANK($V$3:$V$184,V11) -> 0.955 | Y11: 30418 | Z11: 422.5 | AA11: =PERCENTRANK($Z$3:$Z$241,Z11) -> 0.957
A12: 40130 | B12: 15.9 | C12: =PERCENTRANK($B$3:$B$241,B12) -> 0.957 | E12: 10101 | F12: 5695264.1 | G12: =PERCENTRANK($F$3:$F$241,F12) -> 0.962 | I12: 40203 | J12: 278462.32 | K12: =PERCENTRANK($J$3:$J$118,J12) -> 0.921 | M12: 40206 | N12: 1424894.4 | O12: =PERCENTRANK($N$3:$N$241,N12) -> 0.962 | Q12: 40145 | R12: 521121.5 | S12: =PERCENTRANK($R$3:$R$241,R12) -> 0.962 | U12: 30614 | V12: 57919.07 | W12: =PERCENTRANK($V$3:$V$184,V12) -> 0.95 | Y12: 40144 | Z12: 422.5 | AA12: =PERCENTRANK($Z$3:$Z$241,Z12) -> 0.957
A13: 40131 | B13: 15.9 | C13: =PERCENTRANK($B$3:$B$241,B13) -> 0.957 | E13: 11123 | F13: 5417726.9 | G13: =PERCENTRANK($F$3:$F$241,F13) -> 0.957 | I13: 30612 | J13: 278263.8 | K13: =PERCENTRANK($J$3:$J$118,J13) -> 0.913 | M13: 40145 | N13: 1396111 | O13: =PERCENTRANK($N$3:$N$241,N13) -> 0.957 | Q13: 10611 | R13: 495775.66 | S13: =PERCENTRANK($R$3:$R$241,R13) -> 0.957 | U13: 40114 | V13: 57524.93 | W13: =PERCENTRANK($V$3:$V$184,V13) -> 0.944 | Y13: 40206 | Z13: 422.5 | AA13: =PERCENTRANK($Z$3:$Z$241,Z13) -> 0.957
A14: 10120 | B14: 14.65 | C14: =PERCENTRANK($B$3:$B$241,B14) -> 0.953 | E14: 30216 | F14: 5361257.6 | G14: =PERCENTRANK($F$3:$F$241,F14) -> 0.953 | I14: 10737 | J14: 277065.15 | K14: =PERCENTRANK($J$3:$J$118,J14) -> 0.904 | M14: 10120 | N14: 1395393.7 | O14: =PERCENTRANK($N$3:$N$241,N14) -> 0.953 | Q14: 40130 | R14: 494149.6 | S14: =PERCENTRANK($R$3:$R$241,R14) -> 0.953 | U14: 10714 | V14: 57420.61 | W14: =PERCENTRANK($V$3:$V$184,V14) -> 0.939 | Y14: 40130 | Z14: 420 | AA14: =PERCENTRANK($Z$3:$Z$241,Z14) -> 0.949
... A118: 11208 | B118: 7.37 | C118: =PERCENTRANK($B$3:$B$241,B118) -> 0.516 | E118: 40125 | F118: 2779436 | G118: =PERCENTRANK($F$3:$F$241,F118) -> 0.516 | I118: 10101 | J118: 1795.89 | K118: =PERCENTRANK($J$3:$J$118,J118) -> 0 | M118: 11616 | N118: 625385.4 | O118: =PERCENTRANK($N$3:$N$241,N118) -> 0.516 | Q118: 40116 | R118: 60860.32 | S118: =PERCENTRANK($R$3:$R$241,R118) -> 0.516 | U118: 11409 | V118: 135.83 | W118: =PERCENTRANK($V$3:$V$184,V118) -> 0.364 | Y118: 20913 | Z118: 149.5 | AA118: =PERCENTRANK($Z$3:$Z$241,Z118) -> 0.516
A119: 10137 | B119: 7.34 | C119: =PERCENTRANK($B$3:$B$241,B119) -> 0.508 | E119: 10711 | F119: 2766835.9 | G119: =PERCENTRANK($F$3:$F$241,F119) -> 0.512 | M119: 20408 | N119: 624701.18 | O119: =PERCENTRANK($N$3:$N$241,N119) -> 0.512 | Q119: 10507 | R119: 60609.52 | S119: =PERCENTRANK($R$3:$R$241,R119) -> 0.512 | U119: 30602 | V119: 132.5 | W119: =PERCENTRANK($V$3:$V$184,V119) -> 0.359 | Y119: 20513 | Z119: 147.5 | AA119: =PERCENTRANK($Z$3:$Z$241,Z119) -> 0.512
A120: 40204 | B120: 7.34 | C120: =PERCENTRANK($B$3:$B$241,B120) -> 0.508 | E120: 10507 | F120: 2725355.6 | G120: =PERCENTRANK($F$3:$F$241,F120) -> 0.508 | M120: 40114 | N120: 620962.3 | O120: =PERCENTRANK($N$3:$N$241,N120) -> 0.508 | Q120: 40213 | R120: 60262.86 | S120: =PERCENTRANK($R$3:$R$241,R120) -> 0.508 | U120: 30216 | V120: 131.25 | W120: =PERCENTRANK($V$3:$V$184,V120) -> 0.353 | Y120: 11304 | Z120: 147 | AA120: =PERCENTRANK($Z$3:$Z$241,Z120) -> 0.491
A121: 11304 | B121: 7.33 | C121: =PERCENTRANK($B$3:$B$241,B121) -> 0.491 | E121: 11210 | F121: 2709488 | G121: =PERCENTRANK($F$3:$F$241,F121) -> 0.504 | M121: 11601 | N121: 619070.99 | O121: =PERCENTRANK($N$3:$N$241,N121) -> 0.504 | Q121: 40212 | R121: 59994.42 | S121: =PERCENTRANK($R$3:$R$241,R121) -> 0.504 | U121: 30407 | V121: 125.07 | W121: =PERCENTRANK($V$3:$V$184,V121) -> 0.348 | Y121: 11401 | Z121: 147 | AA121: =PERCENTRANK($Z$3:$Z$241,Z121) -> 0.491
A122: 11613 | B122: 7.33 | C122: =PERCENTRANK($B$3:$B$241,B122) -> 0.491 | E122: 11117 | F122: 2698589.3 | G122: =PERCENTRANK($F$3:$F$241,F122) -> 0.5 | M122: 11809 | N122: 618627.31 | O122: =PERCENTRANK($N$3:$N$241,N122) -> 0.5 | Q122: 10133 | R122: 59377.36 | S122: =PERCENTRANK($R$3:$R$241,R122) -> 0.5 | U122: 10137 | V122: 123.83 | W122: =PERCENTRANK($V$3:$V$184,V122) -> 0.342 | Y122: 20205 | Z122: 147 | AA122: =PERCENTRANK($Z$3:$Z$241,Z122) -> 0.491
A123: 11909 | B123: 7.33 | C123: =PERCENTRANK($B$3:$B$241,B123) -> 0.491 | E123: 10744 | F123: 2696635.2 | G123: =PERCENTRANK($F$3:$F$241,F123) -> 0.495 | M123: 11901 | N123: 615457 | O123: =PERCENTRANK($N$3:$N$241,N123) -> 0.495 | Q123: 10736 | R123: 59358.81 | S123: =PERCENTRANK($R$3:$R$241,R123) -> 0.495 | U123: 30612 | V123: 122.92 | W123: =PERCENTRANK($V$3:$V$184,V123) -> 0.337 | Y123: 20215 | Z123: 147 | AA123: =PERCENTRANK($Z$3:$Z$241,Z123) -> 0.491
A124: 30412 | B124: 7.33 | C124: =PERCENTRANK($B$3:$B$241,B124) -> 0.491 | E124: 20903 | F124: 2684685.3 | G124: =PERCENTRANK($F$3:$F$241,F124) -> 0.491 | M124: 20903 | N124: 607140.9 | O124: =PERCENTRANK($N$3:$N$241,N124) -> 0.491 | Q124: 30421 | R124: 59346.21 | S124: =PERCENTRANK($R$3:$R$241,R124) -> 0.491 | U124: 20210 | V124: 119.17 | W124: =PERCENTRANK($V$3:$V$184,V124) -> 0.331 | Y124: 40113 | Z124: 147 | AA124: =PERCENTRANK($Z$3:$Z$241,Z124) -> 0.491
A125: 10605 | B125: 7.29 | C125: =PERCENTRANK($B$3:$B$241,B125) -> 0.487 | E125: 20911 | F125: 2656701.1 | G125: =PERCENTRANK($F$3:$F$241,F125) -> 0.487 | M125: 40208 | N125: 606018.83 | O125: =PERCENTRANK($N$3:$N$241,N125) -> 0.487 | Q125: 20513 | R125: 59325.93 | S125: =PERCENTRANK($R$3:$R$241,R125) -> 0.487 | U125: 10724 | V125: 112.91 | W125: =PERCENTRANK($V$3:$V$184,V125) -> 0.325 | Y125: 20905 | Z125: 145.5 | AA125: =PERCENTRANK($Z$3:$Z$241,Z125) -> 0.487
A126: 11204 | B126: 7.17 | C126: =PERCENTRANK($B$3:$B$241,B126) -> 0.478 | E126: 11109 | F126: 2654291.3 | G126: =PERCENTRANK($F$3:$F$241,F126) -> 0.483 | M126: 11909 | N126: 595237.39 | O126: =PERCENTRANK($N$3:$N$241,N126) -> 0.483 | Q126: 30618 | R126: 59123.46 | S126: =PERCENTRANK($R$3:$R$241,R126) -> 0.483 | U126: 10118 | V126: 106.25 | W126: =PERCENTRANK($V$3:$V$184,V126) -> 0.32 | Y126: 11510 | Z126: 144.5 | AA126: =PERCENTRANK($Z$3:$Z$241,Z126) -> 0.483
A127: 40147 | B127: 7.17 | C127: =PERCENTRANK($B$3:$B$241,B127) -> 0.478 | E127: 30615 | F127: 2652588.4 | G127: =PERCENTRANK($F$3:$F$241,F127) -> 0.478 | M127: 11211 | N127: 591154.3 | O127: =PERCENTRANK($N$3:$N$241,N127) -> 0.478 | Q127: 10518 | R127: 58935.57 | S127: =PERCENTRANK($R$3:$R$241,R127) -> 0.478 | U127: 20433 | V127: 105 | W127: =PERCENTRANK($V$3:$V$184,V127) -> 0.314 | Y127: 11210 | Z127: 142 | AA127: =PERCENTRANK($Z$3:$Z$241,Z127) -> 0.466
A128: 10501 | B128: 7.12 | C128: =PERCENTRANK($B$3:$B$241,B128) -> 0.474 | E128: 40120 | F128: 2640531.7 | G128: =PERCENTRANK($F$3:$F$241,F128) -> 0.474 | M128: 11710 | N128: 590586.08 | O128: =PERCENTRANK($N$3:$N$241,N128) -> 0.474 | Q128: 20408 | R128: 57990.55 | S128: =PERCENTRANK($R$3:$R$241,R128) -> 0.474 | U128: 20909 | V128: 95.41 | W128: =PERCENTRANK($V$3:$V$184,V128) -> 0.309 | Y128: 20908 | Z128: 142 | AA128: =PERCENTRANK($Z$3:$Z$241,Z128) -> 0.466
A129: 10128 | B129: 7.09 | C129: =PERCENTRANK($B$3:$B$241,B129) -> 0.457 | E129: 10714 | F129: 2625498.1 | G129: =PERCENTRANK($F$3:$F$241,F129) -> 0.47 | M129: 11814 | N129: 590372.06 | O129: =PERCENTRANK($N$3:$N$241,N129) -> 0.47 | Q129: 11509 | R129: 57859.35 | S129: =PERCENTRANK($R$3:$R$241,R129) -> 0.47 | U129: 11117 | V129: 92.08 | W129: =PERCENTRANK($V$3:$V$184,V129) -> 0.303 | Y129: 30402 | Z129: 142 | AA129: =PERCENTRANK($Z$3:$Z$241,Z129) -> 0.466
A130: 11509 | B130: 7.09 | C130: =PERCENTRANK($B$3:$B$241,B130) -> 0.457 | E130: 11708 | F130: 2624579.5 | G130: =PERCENTRANK($F$3:$F$241,F130) -> 0.466 | M130: 40213 | N130: 589590.25 | O130: =PERCENTRANK($N$3:$N$241,N130) -> 0.466 | Q130: 30612 | R130: 57858.74 | S130: =PERCENTRANK($R$3:$R$241,R130) -> 0.466 | U130: 30619 | V130: 91.69 | W130: =PERCENTRANK($V$3:$V$184,V130) -> 0.298 | Y130: 30618 | Z130: 142 | AA130: =PERCENTRANK($Z$3:$Z$241,Z130) -> 0.466
... A184: 20431 | B184: 5.63 | C184: =PERCENTRANK($B$3:$B$241,B184) -> 0.239 | E184: 11311 | F184: 2077951.7 | G184: =PERCENTRANK($F$3:$F$241,F184) -> 0.239 | M184: 20526 | N184: 459644.27 | O184: =PERCENTRANK($N$3:$N$241,N184) -> 0.239 | Q184: 20909 | R184: 41164.56 | S184: =PERCENTRANK($R$3:$R$241,R184) -> 0.239 | U184: 10105 | V184: 0.83 | W184: =PERCENTRANK($V$3:$V$184,V184) -> 0 | Y184: 40204 | Z184: 110.5 | AA184: =PERCENTRANK($Z$3:$Z$241,Z184) -> 0.235
A185: 10744 | B185: 5.62 | C185: =PERCENTRANK($B$3:$B$241,B185) -> 0.231 | E185: 11214 | F185: 2076453 | G185: =PERCENTRANK($F$3:$F$241,F185) -> 0.235 | M185: 20908 | N185: 447651.29 | O185: =PERCENTRANK($N$3:$N$241,N185) -> 0.235 | Q185: 10714 | R185: 40906.56 | S185: =PERCENTRANK($R$3:$R$241,R185) -> 0.235 | Y185: 40207 | Z185: 110.5 | AA185: =PERCENTRANK($Z$3:$Z$241,Z185) -> 0.235
A186: 20526 | B186: 5.62 | C186: =PERCENTRANK($B$3:$B$241,B186) -> 0.231 | E186: 20909 | F186: 2075138.2 | G186: =PERCENTRANK($F$3:$F$241,F186) -> 0.231 | M186: 10118 | N186: 446076.93 | O186: =PERCENTRANK($N$3:$N$241,N186) -> 0.231 | Q186: 40202 | R186: 40474.91 | S186: =PERCENTRANK($R$3:$R$241,R186) -> 0.231 | Y186: 10118 | Z186: 109.5 | AA186: =PERCENTRANK($Z$3:$Z$241,Z186) -> 0.218
A187: 11117 | B187: 5.6 | C187: =PERCENTRANK($B$3:$B$241,B187) -> 0.226 | E187: 11606 | F187: 2065301.9 | G187: =PERCENTRANK($F$3:$F$241,F187) -> 0.226 | M187: 40106 | N187: 441644.51 | O187: =PERCENTRANK($N$3:$N$241,N187) -> 0.226 | Q187: 11311 | R187: 40126.87 | S187: =PERCENTRANK($R$3:$R$241,R187) -> 0.226 | Y187: 11116 | Z187: 109.5 | AA187: =PERCENTRANK($Z$3:$Z$241,Z187) -> 0.218
A188: 11708 | B188: 5.53 | C188: =PERCENTRANK($B$3:$B$241,B188) -> 0.222 | E188: 11502 | F188: 2061993.6 | G188: =PERCENTRANK($F$3:$F$241,F188) -> 0.222 | M188: 40115 | N188: 440165.9 | O188: =PERCENTRANK($N$3:$N$241,N188) -> 0.222 | Q188: 11911 | R188: 40083.43 | S188: =PERCENTRANK($R$3:$R$241,R188) -> 0.222 | Y188: 11618 | Z188: 109.5 | AA188: =PERCENTRANK($Z$3:$Z$241,Z188) -> 0.218
A189: 11212 | B189: 5.5 | C189: =PERCENTRANK($B$3:$B$241,B189) -> 0.218 | E189: 11417 | F189: 2052483.3 | G189: =PERCENTRANK($F$3:$F$241,F189) -> 0.218 | M189: 10144 | N189: 437925.83 | O189: =PERCENTRANK($N$3:$N$241,N189) -> 0.218 | Q189: 20421 | R189: 39433.72 | S189: =PERCENTRANK($R$3:$R$241,R189) -> 0.218 | Y189: 11904 | Z189: 109.5 | AA189: =PERCENTRANK($Z$3:$Z$241,Z189) -> 0.218
A190: 40127 | B190: 5.38 | C190: =PERCENTRANK($B$3:$B$241,B190) -> 0.214 | E190: 40116 | F190: 2032888.7 | G190: =PERCENTRANK($F$3:$F$241,F190) -> 0.214 | M190: 40204 | N190: 435825.78 | O190: =PERCENTRANK($N$3:$N$241,N190) -> 0.214 | Q190: 20433 | R190: 38451.56 | S190: =PERCENTRANK($R$3:$R$241,R190) -> 0.214 | Y190: 11406 | Z190: 108 | AA190: =PERCENTRANK($Z$3:$Z$241,Z190) -> 0.205
A191: 11911 | B191: 5.27 | C191: =PERCENTRANK($B$3:$B$241,B191) -> 0.205 | E191: 10137 | F191: 2011947.9 | G191: =PERCENTRANK($F$3:$F$241,F191) -> 0.21 | M191: 40126 | N191: 431632.78 | O191: =PERCENTRANK($N$3:$N$241,N191) -> 0.21 | Q191: 11403 | R191: 38434.5 | S191: =PERCENTRANK($R$3:$R$241,R191) -> 0.21 | Y191: 40106 | Z191: 108 | AA191: =PERCENTRANK($Z$3:$Z$241,Z191) -> 0.205
A192: 20424 | B192: 5.27 | C192: =PERCENTRANK($B$3:$B$241,B192) -> 0.205 | E192: 11616 | F192: 1995794.6 | G192: =PERCENTRANK($F$3:$F$241,F192) -> 0.205 | M192: 10502 | N192: 427230.64 | O192: =PERCENTRANK($N$3:$N$241,N192) -> 0.205 | Q192: 11618 | R192: 38401.3 | S192: =PERCENTRANK($R$3:$R$241,R192) -> 0.205 | Y192: 40127 | Z192: 108 | AA192: =PERCENTRANK($Z$3:$Z$241,Z192) -> 0.205
A193: 11312 | B193: 5.24 | C193: =PERCENTRANK($B$3:$B$241,B193) -> 0.201 | E193: 20526 | F193: 1993781.7 | G193: =PERCENTRANK($F$3:$F$241,F193) -> 0.201 | M193: 40146 | N193: 422698.58 | O193: =PERCENTRANK($N$3:$N$241,N193) -> 0.201 | Q193: 10128 | R193: 38159.43 | S193: =PERCENTRANK($R$3:$R$241,R193) -> 0.201 | Y193: 10140 | Z193: 105.5 | AA193: =PERCENTRANK($Z$3:$Z$241,Z193) -> 0.189
A194: 20513 | B194: 5.23 | C194: =PERCENTRANK($B$3:$B$241,B194) -> 0.197 | E194: 11814 | F194: 1993302.2 | G194: =PERCENTRANK($F$3:$F$241,F194) -> 0.197 | M194: 11117 | N194: 413349.44 | O194: =PERCENTRANK($N$3:$N$241,N194) -> 0.197 | Q194: 30407 | R194: 37917.6 | S194: =PERCENTRANK($R$3:$R$241,R194) -> 0.197 | Y194: 11814 | Z194: 105.5 | AA194: =PERCENTRANK($Z$3:$Z$241,Z194) -> 0.189
A195: 10118 | B195: 5.21 | C195: =PERCENTRANK($B$3:$B$241,B195) -> 0.193 | E195: 40105 | F195: 1985072.4 | G195: =PERCENTRANK($F$3:$F$241,F195) -> 0.193 | M195: 20909 | N195: 410894.02 | O195: =PERCENTRANK($N$3:$N$241,N195) -> 0.193 | Q195: 10137 | R195: 37624.14 | S195: =PERCENTRANK($R$3:$R$241,R195) -> 0.193 | Y195: 20421 | Z195: 105.5 | AA195: =PERCENTRANK($Z$3:$Z$241,Z195) -> 0.189
A196: 20421 | B196: 5.18 | C196: =PERCENTRANK($B$3:$B$241,B196) -> 0.189 | E196: 40208 | F196: 1980024.3 | G196: =PERCENTRANK($F$3:$F$241,F196) -> 0.189 | M196: 11602 | N196: 410323.16 | O196: =PERCENTRANK($N$3:$N$241,N196) -> 0.189 | Q196: 10140 | R196: 37361.78 | S196: =PERCENTRANK($R$3:$R$241,R196) -> 0.189 | Y196: 20511 | Z196: 105.5 | AA196: =PERCENTRANK($Z$3:$Z$241,Z196) -> 0.189
...

Sheet kalkulačka
B1: X | F1: =COUNT(B2:B275) -> 19
B2: 4943.49 | C2: NO FC | D2: 1 | F2: 0.1 | G2: 0.2 | H2: 0.4 | I2: 0.3
B3: 4502.59 | C3: NO FC | D3: 2 | F3: =ROUNDUP(F1*10%,0) -> 2 | G3: =ROUNDUP(F1*F2+F1*G2,0) -> 6 | H3: =ROUNDUP(F1*F2+F1*G2+F1*H2,0) -> 14 | M3: 27 | N3: =M3/SUM($M$3:$M$6) -> 0.099630996
B4: 3878.79 | C4: NO FC | D4: 3 | F4: =_xlfn.XLOOKUP(F$3,$D:$D,$B:$B,0,0) -> 4502.59 | G4: =_xlfn.XLOOKUP(G$3,$D:$D,$B:$B,0,0) -> 2379.1 | H4: =_xlfn.XLOOKUP(H$3,$D:$D,$B:$B,0,0) -> 0 | M4: 52 | N4: =M4/SUM($M$3:$M$6) -> 0.19188192
B5: 3138.19 | C5: NO FC | D5: 4 | M5: 110 | N5: =M5/SUM($M$3:$M$6) -> 0.40590406
B6: 2781.83 | C6: NO FC | D6: 5 | M6: 82 | N6: =M6/SUM($M$3:$M$6) -> 0.30258303
B7: 2379.1 | C7: NO FC | D7: 6
B8: 2119.53 | C8: NO FC | D8: 7
B9: 2111.8 | C9: NO FC | D9: 8
B10: 1906.87 | C10: NO FC | D10: 9
B11: 1279.9 | C11: NO FC | D11: 10
B12: 1064.18 | C12: NO FC | D12: 11
B13: 0 | C13: NO FC | D13: 12
B14: 0 | C14: NO FC | D14: 13
B15: 0 | C15: NO FC | D15: 14
B16: 0 | C16: NO FC | D16: 15
B17: 0 | C17: NO FC | D17: 16
B18: 0 | C18: NO FC | D18: 17
... B20: 0 | C20: NO FC | D20: 19
D21: 20
D22: 21
D23: 22
D24: 23
D25: 24
D26: 25
D27: 26
D28: 27
D29: 28
D30: 29
D31: 30
D32: 31
... D275: 274

Sheet Sheet1
A1: Code | B1: SeS name | C1: old fee | D1: new fee | E1: diff | F1: koment | H1: Sum of diff | O1: Increase/Decrease | P1: Ses Name | Q1: Suma
A2: 10748 | B2: Zeleneč I. | C2: 300 | D2: 300 | E2: =D2-C2 -> 0 | F2: =IF(E2>0,"Increase",IF(E2<0,"Decrase",0)) -> 0 | H2: koment | I2: SeS name | J2: Total | O2: Decrase | P2: Bánovce nad Bebravou - Trenčianska II. | Q2: -100
A3: 10612 | B3: Sekule I. | C3: 300 | D3: 300 | E3: =D3-C3 -> 0 | F3: =IF(E3>0,"Increase",IF(E3<0,"Decrase",0)) -> 0 | H3: 0 | I3: Bánovce nad Bebravou | J3: 0 | P3: Bardejov-Prešovská | Q3: -100
A4: 30418 | B4: Štrba | C4: 300 | D4: 300 | E4: =D4-C4 -> 0 | F4: =IF(E4>0,"Increase",IF(E4<0,"Decrase",0)) -> 0 | I4: Banská Bystrica-Jakub | J4: 0 | P4: Bošany | Q4: -50
A5: 11412 | B5: Trenčín-Zamarovce | C5: 300 | D5: 300 | E5: =D5-C5 -> 0 | F5: =IF(E5>0,"Increase",IF(E5<0,"Decrase",0)) -> 0 | I5: Banská Bystrica-Kremnička | J5: 0 | P5: Bratislava - Dolnozemská II. | Q5: -100
A6: 10611 | B6: Sekule II. | C6: 300 | D6: 300 | E6: =D6-C6 -> 0 | F6: =IF(E6>0,"Increase",IF(E6<0,"Decrase",0)) -> 0 | I6: Banská Bystrica-Partizánska | J6: 0 | P6: Bratislava - Dúbravka II. | Q6: -50
A7: 10105 | B7: Bratislava-DČS Zlaté Piesky | C7: 300 | D7: 300 | E7: =D7-C7 -> 0 | F7: =IF(E7>0,"Increase",IF(E7<0,"Decrase",0)) -> 0 | I7: Banská Bystrica-Rudlovská | J7: 0 | P7: Bratislava-Bajkalská II. | Q7: -100
A8: 30608 | B8: Malý Šariš-sever | C8: 300 | D8: 300 | E8: =D8-C8 -> 0 | F8: =IF(E8>0,"Increase",IF(E8<0,"Decrase",0)) -> 0 | I8: Banská Bystrica-Štiavničky | J8: 0 | P8: Bratislava-Botanická | Q8: -100
A9: 10706 | B9: Ilava II. | C9: 300 | D9: 300 | E9: =D9-C9 -> 0 | F9: =IF(E9>0,"Increase",IF(E9<0,"Decrase",0)) -> 0 | I9: Banská Bystrica-Zvolenská | J9: 0 | P9: Bratislava-Petržalka I. | Q9: -100
A10: 10101 | B10: Bratislava-Záhorská Bystrica | C10: 200 | D10: 200 | E10: =D10-C10 -> 0 | F10: =IF(E10>0,"Increase",IF(E10<0,"Decrase",0)) -> 0 | I10: Banská Štiavnica | J10: 0 | P10: Bratislava-ul.Sch.-Trnavského | Q10: -50
A11: 40141 | B11: Žilina-Kysucká | C11: 200 | D11: 300 | E11: =D11-C11 -> 100 | F11: =IF(E11>0,"Increase",IF(E11<0,"Decrase",0)) -> Increase | I11: Beladice | J11: 0 | P11: Bratislava-Vrakunská | Q11: -100
A12: 11701 | B12: Bytča | C12: 300 | D12: 300 | E12: =D12-C12 -> 0 | F12: =IF(E12>0,"Increase",IF(E12<0,"Decrase",0)) -> 0 | I12: Bernolákovo | J12: 0 | P12: Dubnica nad Váhom | Q12: -50
A13: 20216 | B13: Ivachnová | C13: 300 | D13: 300 | E13: =D13-C13 -> 0 | F13: =IF(E13>0,"Increase",IF(E13<0,"Decrase",0)) -> 0 | I13: Blatná na Ostrove | J13: 0 | P13: Dunajská Lužná | Q13: -100
A14: 40131 | B14: Budča-Sever | C14: 300 | D14: 300 | E14: =D14-C14 -> 0 | F14: =IF(E14>0,"Increase",IF(E14<0,"Decrase",0)) -> 0 | I14: Bratislava - Panónska | J14: 0 | P14: Dunajská Streda-Bratislavská I. | Q14: -50
A15: 40130 | B15: Budča-Juh | C15: 300 | D15: 300 | E15: =D15-C15 -> 0 | F15: =IF(E15>0,"Increase",IF(E15<0,"Decrase",0)) -> 0 | I15: Bratislava – Prístavná | J15: 0 | P15: Gabčíkovo | Q15: -50
... A58: 40108 | B58: Bánovce nad Bebravou - Trenčianska II. | C58: 200 | D58: 100 | E58: =D58-C58 -> -100 | F58: =IF(E58>0,"Increase",IF(E58<0,"Decrase",0)) -> Decrase | I58: Košice - Textilná | J58: 0 | P58: Žilina-Vysokoškolákov | Q58: -100
A59: 20913 | B59: Liptovský Hrádok-Pod celinami | C59: 200 | D59: 100 | E59: =D59-C59 -> -100 | F59: =IF(E59>0,"Increase",IF(E59<0,"Decrase",0)) -> Decrase | I59: Košice-Alejová | J59: 0 | O59: Increase | P59: Bardejov-Duklianska | Q59: 100
A60: 11122 | B60: Veľký Meder | C60: 100 | D60: 100 | E60: =D60-C60 -> 0 | F60: =IF(E60>0,"Increase",IF(E60<0,"Decrase",0)) -> 0 | I60: Košice-Barca | J60: 0 | P60: Bratislava-Zlaté Piesky | Q60: 100
A61: 11507 | B61: Senica | C61: 200 | D61: 200 | E61: =D61-C61 -> 0 | F61: =IF(E61>0,"Increase",IF(E61<0,"Decrase",0)) -> 0 | I61: Košice-Festivalové námestie | J61: 0 | P61: DČS Hrádok | Q61: 100
A62: 40120 | B62: Holíč-Bratislavská | C62: 200 | D62: 100 | E62: =D62-C62 -> -100 | F62: =IF(E62>0,"Increase",IF(E62<0,"Decrase",0)) -> Decrase | I62: Košice-Hutnícka | J62: 0 | P62: Košice - Dargovských hrdinov | Q62: 50
A63: 20401 | B63: Banská Bystrica-Partizánska | C63: 200 | D63: 200 | E63: =D63-C63 -> 0 | F63: =IF(E63>0,"Increase",IF(E63<0,"Decrase",0)) -> 0 | I63: Košice-Jantárová | J63: 0 | P63: Ľubotice​ | Q63: 100
A64: 10527 | B64: Nová Baňa | C64: 200 | D64: 100 | E64: =D64-C64 -> -100 | F64: =IF(E64>0,"Increase",IF(E64<0,"Decrase",0)) -> Decrase | I64: Košice-KVP | J64: 0 | P64: Malacky | Q64: 100
A65: 40118 | B65: Dunajská Lužná | C65: 200 | D65: 100 | E65: =D65-C65 -> -100 | F65: =IF(E65>0,"Increase",IF(E65<0,"Decrase",0)) -> Decrase | I65: Košice-Luník | J65: 0 | P65: Malý Šariš-juh | Q65: 100
A66: 40129 | B66: Banská Bystrica-Zvolenská | C66: 200 | D66: 200 | E66: =D66-C66 -> 0 | F66: =IF(E66>0,"Increase",IF(E66<0,"Decrase",0)) -> 0 | I66: Košice-Moldavská | J66: 0 | P66: Pohranice - Sever | Q66: 100
A67: 40102 | B67: Janovík-Západ | C67: 200 | D67: 200 | E67: =D67-C67 -> 0 | F67: =IF(E67>0,"Increase",IF(E67<0,"Decrase",0)) -> 0 | I67: Košice-Poľov | J67: 0 | P67: Prešov-Levočská | Q67: 100
A68: 40138 | B68: Považská Bystrica-Slovenských partizánov | C68: 200 | D68: 200 | E68: =D68-C68 -> 0 | F68: =IF(E68>0,"Increase",IF(E68<0,"Decrase",0)) -> 0 | I68: Košice-Sečovská | J68: 0 | P68: Trebišov-Hlavná | Q68: 100
A69: 20404 | B69: Brezno | C69: 200 | D69: 200 | E69: =D69-C69 -> 0 | F69: =IF(E69>0,"Increase",IF(E69<0,"Decrase",0)) -> 0 | I69: Košice-Šaca | J69: 0 | P69: Trenčianska Turná | Q69: 100
A70: 11211 | B70: Malacky | C70: 100 | D70: 200 | E70: =D70-C70 -> 100 | F70: =IF(E70>0,"Increase",IF(E70<0,"Decrase",0)) -> Increase | I70: Kráľovský Chlmec II. | J70: 0 | P70: Zvolen-Neresnícka | Q70: 100
A71: 40125 | B71: Bratislava-Bratská | C71: 200 | D71: 200 | E71: =D71-C71 -> 0 | F71: =IF(E71>0,"Increase",IF(E71<0,"Decrase",0)) -> 0 | I71: Kremnica | J71: 0 | P71: Žilina-Kysucká | Q71: 100
A72: 30412 | B72: Spišská Nová Ves-Markušovská | C72: 200 | D72: 100 | E72: =D72-C72 -> -100 | F72: =IF(E72>0,"Increase",IF(E72<0,"Decrase",0)) -> Decrase | I72: Krompachy | J72: 0 | O72: Grand Total | Q72: -2850
A73: 40121 | B73: Senec - Senecká | C73: 200 | D73: 200 | E73: =D73-C73 -> 0 | F73: =IF(E73>0,"Increase",IF(E73<0,"Decrase",0)) -> 0 | I73: Krupina | J73: 0
A74: 11811 | B74: Sobrance | C74: 100 | D74: 100 | E74: =D74-C74 -> 0 | F74: =IF(E74>0,"Increase",IF(E74<0,"Decrase",0)) -> 0 | I74: Kúty | J74: 0
A75: 40142 | B75: Košice-Poľov | C75: 200 | D75: 200 | E75: =D75-C75 -> 0 | F75: =IF(E75>0,"Increase",IF(E75<0,"Decrase",0)) -> 0 | I75: Lednické Rovne | J75: 0
A76: 30207 | B76: Michalovce - Sobranecká | C76: 200 | D76: 200 | E76: =D76-C76 -> 0 | F76: =IF(E76>0,"Increase",IF(E76<0,"Decrase",0)) -> 0 | I76: Levice-Družstevnícka | J76: 0
A77: 30205 | B77: Michalovce-Močaranská | C77: 100 | D77: 100 | E77: =D77-C77 -> 0 | F77: =IF(E77>0,"Increase",IF(E77<0,"Decrase",0)) -> 0 | I77: Levice-Ku Bratke | J77: 0
A78: 11509 | B78: Trnava-Bratislavská | C78: 100 | D78: 100 | E78: =D78-C78 -> 0 | F78: =IF(E78>0,"Increase",IF(E78<0,"Decrase",0)) -> 0 | I78: Liptovský Mikuláš-Okoličné | J78: 0
A79: 11901 | B79: Bardejov-Prešovská | C79: 200 | D79: 100 | E79: =D79-C79 -> -100 | F79: =IF(E79>0,"Increase",IF(E79<0,"Decrase",0)) -> Decrase | I79: Lučenec-Opatová | J79: 0
A80: 30127 | B80: Rožňava-Brzotín | C80: 200 | D80: 200 | E80: =D80-C80 -> 0 | F80: =IF(E80>0,"Increase",IF(E80<0,"Decrase",0)) -> 0 | I80: Madunice | J80: 0
A81: 11417 | B81: Sverepec | C81: 200 | D81: 200 | E81: =D81-C81 -> 0 | F81: =IF(E81>0,"Increase",IF(E81<0,"Decrase",0)) -> 0 | I81: Malý Šariš-sever | J81: 0
A82: 30612 | B82: Prešov-Levočská | C82: 100 | D82: 200 | E82: =D82-C82 -> 100 | F82: =IF(E82>0,"Increase",IF(E82<0,"Decrase",0)) -> Increase | I82: Martin-Francúzskych partizánov | J82: 0
...

Sheet NEW MODEL SUMMARY
F4: CATEGORIZATION
M5: =COUNTIFS('NEW MODEL BY SES'!X19:X390,"I",'NEW MODEL BY SES'!A19:A390,) -> 0
B6: CATEGORY COMPARISON | C6: No. of SeS by Category CURRENT | F6: No. of SeS by Category NEW MODEL | I6: Difference | K6: Region | L6: Area Manager | M6: Category
B7: COCA | D7: =E7/$E$7 -> #VALUE! | E7: =SUM(E8:E11) -> #VALUE! | G7: =H7/$H$7 -> #DIV/0! | H7: =SUM(H8:H11) -> 0 | M7: I | N7: II | O7: III | P7: IV | Q7: Total
D8: =E8/$E$7 -> #VALUE! | E8: =COUNTIFS('NEW MODEL BY SES'!$D$19:$D$242,$B$7,'NEW MODEL BY SES'!$AA$21:$AA$242,$C8) -> #VALUE! | F8: I | G8: =H8/$H$7 -> #DIV/0! | H8: =COUNTIFS('NEW MODEL BY SES'!$D$19:$D$242,$B$7,'NEW MODEL BY SES'!$X$19:$X$242,$F8) -> 0 | I8: =H8-E8 -> #VALUE! | L8: {=_xlfn.UNIQUE('NEW MODEL BY SES'!A19:A429)} -> Area Manager 1 | M8: =COUNTIFS('NEW MODEL BY SES'!$X$19:$X$429,M$7,'NEW MODEL BY SES'!$A$19:$A$429,$L8) -> 1 | N8: =COUNTIFS('NEW MODEL BY SES'!$X$19:$X$429,N$7,'NEW MODEL BY SES'!$A$19:$A$429,$L8) -> 9 | O8: =COUNTIFS('NEW MODEL BY SES'!$X$19:$X$429,O$7,'NEW MODEL BY SES'!$A$19:$A$429,$L8) -> 9 | P8: =COUNTIFS('NEW MODEL BY SES'!$X$19:$X$429,P$7,'NEW MODEL BY SES'!$A$19:$A$429,$L8) -> 6 | Q8: =SUM(M8:P8) -> 25
C9: III | D9: =E9/$E$7 -> #VALUE! | E9: =COUNTIFS('NEW MODEL BY SES'!$D$19:$D$242,$B$7,'NEW MODEL BY SES'!$AA$21:$AA$242,$C9) -> #VALUE! | F9: II | G9: =H9/$H$7 -> #DIV/0! | H9: =COUNTIFS('NEW MODEL BY SES'!$D$19:$D$242,$B$7,'NEW MODEL BY SES'!$X$19:$X$242,$F9) -> 0 | I9: =H9-E9 -> #VALUE! | L9: Area Manager 2 | M9: =COUNTIFS('NEW MODEL BY SES'!$X$19:$X$429,M$7,'NEW MODEL BY SES'!$A$19:$A$429,$L9) -> 2 | N9: =COUNTIFS('NEW MODEL BY SES'!$X$19:$X$429,N$7,'NEW MODEL BY SES'!$A$19:$A$429,$L9) -> 4 | O9: =COUNTIFS('NEW MODEL BY SES'!$X$19:$X$429,O$7,'NEW MODEL BY SES'!$A$19:$A$429,$L9) -> 13 | P9: =COUNTIFS('NEW MODEL BY SES'!$X$19:$X$429,P$7,'NEW MODEL BY SES'!$A$19:$A$429,$L9) -> 4 | Q9: =SUM(M9:P9) -> 23
C10: II | D10: =E10/$E$7 -> #VALUE! | E10: =COUNTIFS('NEW MODEL BY SES'!$D$19:$D$242,$B$7,'NEW MODEL BY SES'!$AA$21:$AA$242,$C10) -> #VALUE! | F10: III | G10: =H10/$H$7 -> #DIV/0! | H10: =COUNTIFS('NEW MODEL BY SES'!$D$19:$D$242,$B$7,'NEW MODEL BY SES'!$X$19:$X$242,$F10) -> 0 | I10: =H10-E10 -> #VALUE! | L10: Area Manager 3 | M10: =COUNTIFS('NEW MODEL BY SES'!$X$19:$X$429,M$7,'NEW MODEL BY SES'!$A$19:$A$429,$L10) -> 4 | N10: =COUNTIFS('NEW MODEL BY SES'!$X$19:$X$429,N$7,'NEW MODEL BY SES'!$A$19:$A$429,$L10) -> 6 | O10: =COUNTIFS('NEW MODEL BY SES'!$X$19:$X$429,O$7,'NEW MODEL BY SES'!$A$19:$A$429,$L10) -> 6 | P10: =COUNTIFS('NEW MODEL BY SES'!$X$19:$X$429,P$7,'NEW MODEL BY SES'!$A$19:$A$429,$L10) -> 5 | Q10: =SUM(M10:P10) -> 21
C11: I | D11: =E11/$E$7 -> #VALUE! | E11: =COUNTIFS('NEW MODEL BY SES'!$D$19:$D$242,$B$7,'NEW MODEL BY SES'!$AA$21:$AA$242,$C11) -> #VALUE! | F11: IV | G11: =H11/$H$7 -> #DIV/0! | H11: =COUNTIFS('NEW MODEL BY SES'!$D$19:$D$242,$B$7,'NEW MODEL BY SES'!$X$19:$X$242,$F11) -> 0 | I11: =H11-E11 -> #VALUE! | L11: Area Manager 4 | M11: =COUNTIFS('NEW MODEL BY SES'!$X$19:$X$429,M$7,'NEW MODEL BY SES'!$A$19:$A$429,$L11) -> 3 | N11: =COUNTIFS('NEW MODEL BY SES'!$X$19:$X$429,N$7,'NEW MODEL BY SES'!$A$19:$A$429,$L11) -> 5 | O11: =COUNTIFS('NEW MODEL BY SES'!$X$19:$X$429,O$7,'NEW MODEL BY SES'!$A$19:$A$429,$L11) -> 13 | P11: =COUNTIFS('NEW MODEL BY SES'!$X$19:$X$429,P$7,'NEW MODEL BY SES'!$A$19:$A$429,$L11) -> 6 | Q11: =SUM(M11:P11) -> 27
L12: Area Manager 5 | M12: =COUNTIFS('NEW MODEL BY SES'!$X$19:$X$429,M$7,'NEW MODEL BY SES'!$A$19:$A$429,$L12) -> 6 | N12: =COUNTIFS('NEW MODEL BY SES'!$X$19:$X$429,N$7,'NEW MODEL BY SES'!$A$19:$A$429,$L12) -> 7 | O12: =COUNTIFS('NEW MODEL BY SES'!$X$19:$X$429,O$7,'NEW MODEL BY SES'!$A$19:$A$429,$L12) -> 6 | P12: =COUNTIFS('NEW MODEL BY SES'!$X$19:$X$429,P$7,'NEW MODEL BY SES'!$A$19:$A$429,$L12) -> 4 | Q12: =SUM(M12:P12) -> 23
L13: Area Manager 6 | M13: =COUNTIFS('NEW MODEL BY SES'!$X$19:$X$429,M$7,'NEW MODEL BY SES'!$A$19:$A$429,$L13) -> 0 | N13: =COUNTIFS('NEW MODEL BY SES'!$X$19:$X$429,N$7,'NEW MODEL BY SES'!$A$19:$A$429,$L13) -> 6 | O13: =COUNTIFS('NEW MODEL BY SES'!$X$19:$X$429,O$7,'NEW MODEL BY SES'!$A$19:$A$429,$L13) -> 9 | P13: =COUNTIFS('NEW MODEL BY SES'!$X$19:$X$429,P$7,'NEW MODEL BY SES'!$A$19:$A$429,$L13) -> 14 | Q13: =SUM(M13:P13) -> 29
L14: Area Manager 7 | M14: =COUNTIFS('NEW MODEL BY SES'!$X$19:$X$429,M$7,'NEW MODEL BY SES'!$A$19:$A$429,$L14) -> 3 | N14: =COUNTIFS('NEW MODEL BY SES'!$X$19:$X$429,N$7,'NEW MODEL BY SES'!$A$19:$A$429,$L14) -> 3 | O14: =COUNTIFS('NEW MODEL BY SES'!$X$19:$X$429,O$7,'NEW MODEL BY SES'!$A$19:$A$429,$L14) -> 12 | P14: =COUNTIFS('NEW MODEL BY SES'!$X$19:$X$429,P$7,'NEW MODEL BY SES'!$A$19:$A$429,$L14) -> 12 | Q14: =SUM(M14:P14) -> 30
L15: Area Manager 8 | M15: =COUNTIFS('NEW MODEL BY SES'!$X$19:$X$429,M$7,'NEW MODEL BY SES'!$A$19:$A$429,$L15) -> 6 | N15: =COUNTIFS('NEW MODEL BY SES'!$X$19:$X$429,N$7,'NEW MODEL BY SES'!$A$19:$A$429,$L15) -> 6 | O15: =COUNTIFS('NEW MODEL BY SES'!$X$19:$X$429,O$7,'NEW MODEL BY SES'!$A$19:$A$429,$L15) -> 8 | P15: =COUNTIFS('NEW MODEL BY SES'!$X$19:$X$429,P$7,'NEW MODEL BY SES'!$A$19:$A$429,$L15) -> 9 | Q15: =SUM(M15:P15) -> 29
L16: Area Manager 9 | M16: =COUNTIFS('NEW MODEL BY SES'!$X$19:$X$429,M$7,'NEW MODEL BY SES'!$A$19:$A$429,$L16) -> 8 | N16: =COUNTIFS('NEW MODEL BY SES'!$X$19:$X$429,N$7,'NEW MODEL BY SES'!$A$19:$A$429,$L16) -> 8 | O16: =COUNTIFS('NEW MODEL BY SES'!$X$19:$X$429,O$7,'NEW MODEL BY SES'!$A$19:$A$429,$L16) -> 5 | P16: =COUNTIFS('NEW MODEL BY SES'!$X$19:$X$429,P$7,'NEW MODEL BY SES'!$A$19:$A$429,$L16) -> 2 | Q16: =SUM(M16:P16) -> 23
L17: Area Manager 10 | M17: =COUNTIFS('NEW MODEL BY SES'!$X$19:$X$429,M$7,'NEW MODEL BY SES'!$A$19:$A$429,$L17) -> 0 | N17: =COUNTIFS('NEW MODEL BY SES'!$X$19:$X$429,N$7,'NEW MODEL BY SES'!$A$19:$A$429,$L17) -> 5 | O17: =COUNTIFS('NEW MODEL BY SES'!$X$19:$X$429,O$7,'NEW MODEL BY SES'!$A$19:$A$429,$L17) -> 15 | P17: =COUNTIFS('NEW MODEL BY SES'!$X$19:$X$429,P$7,'NEW MODEL BY SES'!$A$19:$A$429,$L17) -> 12 | Q17: =SUM(M17:P17) -> 32
L18: Area Manager 11 | M18: =COUNTIFS('NEW MODEL BY SES'!$X$19:$X$429,M$7,'NEW MODEL BY SES'!$A$19:$A$429,$L18) -> 5 | N18: =COUNTIFS('NEW MODEL BY SES'!$X$19:$X$429,N$7,'NEW MODEL BY SES'!$A$19:$A$429,$L18) -> 4 | O18: =COUNTIFS('NEW MODEL BY SES'!$X$19:$X$429,O$7,'NEW MODEL BY SES'!$A$19:$A$429,$L18) -> 7 | P18: =COUNTIFS('NEW MODEL BY SES'!$X$19:$X$429,P$7,'NEW MODEL BY SES'!$A$19:$A$429,$L18) -> 5 | Q18: =SUM(M18:P18) -> 21
L19: Area Manager 12 | M19: =COUNTIFS('NEW MODEL BY SES'!$X$19:$X$429,M$7,'NEW MODEL BY SES'!$A$19:$A$429,$L19) -> 1 | N19: =COUNTIFS('NEW MODEL BY SES'!$X$19:$X$429,N$7,'NEW MODEL BY SES'!$A$19:$A$429,$L19) -> 4 | O19: =COUNTIFS('NEW MODEL BY SES'!$X$19:$X$429,O$7,'NEW MODEL BY SES'!$A$19:$A$429,$L19) -> 12 | P19: =COUNTIFS('NEW MODEL BY SES'!$X$19:$X$429,P$7,'NEW MODEL BY SES'!$A$19:$A$429,$L19) -> 8 | Q19: =SUM(M19:P19) -> 25
L20: Area Manager 13 | M20: =COUNTIFS('NEW MODEL BY SES'!$X$19:$X$429,M$7,'NEW MODEL BY SES'!$A$19:$A$429,$L20) -> 4 | N20: =COUNTIFS('NEW MODEL BY SES'!$X$19:$X$429,N$7,'NEW MODEL BY SES'!$A$19:$A$429,$L20) -> 5 | O20: =COUNTIFS('NEW MODEL BY SES'!$X$19:$X$429,O$7,'NEW MODEL BY SES'!$A$19:$A$429,$L20) -> 9 | P20: =COUNTIFS('NEW MODEL BY SES'!$X$19:$X$429,P$7,'NEW MODEL BY SES'!$A$19:$A$429,$L20) -> 9 | Q20: =SUM(M20:P20) -> 27
L21: Area Manager 14 | M21: =COUNTIFS('NEW MODEL BY SES'!$X$19:$X$429,M$7,'NEW MODEL BY SES'!$A$19:$A$429,$L21) -> 0 | N21: =COUNTIFS('NEW MODEL BY SES'!$X$19:$X$429,N$7,'NEW MODEL BY SES'!$A$19:$A$429,$L21) -> 6 | O21: =COUNTIFS('NEW MODEL BY SES'!$X$19:$X$429,O$7,'NEW MODEL BY SES'!$A$19:$A$429,$L21) -> 9 | P21: =COUNTIFS('NEW MODEL BY SES'!$X$19:$X$429,P$7,'NEW MODEL BY SES'!$A$19:$A$429,$L21) -> 8 | Q21: =SUM(M21:P21) -> 23
K22: Total | L22: Area Manager 18 | M22: =COUNTIFS('NEW MODEL BY SES'!$X$19:$X$429,M$7,'NEW MODEL BY SES'!$A$19:$A$429,$L22) -> 0 | N22: =COUNTIFS('NEW MODEL BY SES'!$X$19:$X$429,N$7,'NEW MODEL BY SES'!$A$19:$A$429,$L22) -> 3 | O22: =COUNTIFS('NEW MODEL BY SES'!$X$19:$X$429,O$7,'NEW MODEL BY SES'!$A$19:$A$429,$L22) -> 0 | P22: =COUNTIFS('NEW MODEL BY SES'!$X$19:$X$429,P$7,'NEW MODEL BY SES'!$A$19:$A$429,$L22) -> 1 | Q22: =SUM(M22:P22) -> 4
L23: Area Manager 16 | M23: =COUNTIFS('NEW MODEL BY SES'!$X$19:$X$429,M$7,'NEW MODEL BY SES'!$A$19:$A$429,$L23) -> 0 | N23: =COUNTIFS('NEW MODEL BY SES'!$X$19:$X$429,N$7,'NEW MODEL BY SES'!$A$19:$A$429,$L23) -> 8 | O23: =COUNTIFS('NEW MODEL BY SES'!$X$19:$X$429,O$7,'NEW MODEL BY SES'!$A$19:$A$429,$L23) -> 13 | P23: =COUNTIFS('NEW MODEL BY SES'!$X$19:$X$429,P$7,'NEW MODEL BY SES'!$A$19:$A$429,$L23) -> 3 | Q23: =SUM(M23:P23) -> 24
L24: Area Manager 17 | M24: =COUNTIFS('NEW MODEL BY SES'!$X$19:$X$429,M$7,'NEW MODEL BY SES'!$A$19:$A$429,$L24) -> 3 | N24: =COUNTIFS('NEW MODEL BY SES'!$X$19:$X$429,N$7,'NEW MODEL BY SES'!$A$19:$A$429,$L24) -> 6 | O24: =COUNTIFS('NEW MODEL BY SES'!$X$19:$X$429,O$7,'NEW MODEL BY SES'!$A$19:$A$429,$L24) -> 12 | P24: =COUNTIFS('NEW MODEL BY SES'!$X$19:$X$429,P$7,'NEW MODEL BY SES'!$A$19:$A$429,$L24) -> 4 | Q24: =SUM(M24:P24) -> 25
L25: TOTAL | M25: =SUM(M8:M24) -> 46 | N25: =SUM(N8:N24) -> 95 | O25: =SUM(O8:O24) -> 158 | P25: =SUM(P8:P24) -> 112 | Q25: =SUM(M25:P25) -> 411

Sheet SES_by_category
A1: Code | B1: SeS name | C1: TOTAL SCORE | D1: NEW CATEGORY (ARABIC) | E1: ALFA | F1: fee
A2: 10101 | B2: Bratislava - Záhorská Bystrica | C2: =_xlfn.XLOOKUP(A2,'NEW MODEL BY SES'!B:B,'NEW MODEL BY SES'!AC:AC,0,0) -> 0 | D2: =_xlfn.XLOOKUP(A2,'NEW MODEL BY SES'!B:B,'NEW MODEL BY SES'!AD:AD,0,0) -> 0 | F2: =IF(C2="I",300,IF(C2="II",200,IF(C2="III",100,IF(C2="IV",50)))) -> FALSE
A3: 10103 | B3: Bratislava - Zlaté Piesky | C3: =_xlfn.XLOOKUP(A3,'NEW MODEL BY SES'!B:B,'NEW MODEL BY SES'!AC:AC,0,0) -> 0 | D3: =_xlfn.XLOOKUP(A3,'NEW MODEL BY SES'!B:B,'NEW MODEL BY SES'!AD:AD,0,0) -> 0 | F3: =IF(C3="I",300,IF(C3="II",200,IF(C3="III",100,IF(C3="IV",50)))) -> FALSE
A4: 10105 | B4: Bratislava - DČS Zlaté piesky | C4: =_xlfn.XLOOKUP(A4,'NEW MODEL BY SES'!B:B,'NEW MODEL BY SES'!AC:AC,0,0) -> 0 | D4: =_xlfn.XLOOKUP(A4,'NEW MODEL BY SES'!B:B,'NEW MODEL BY SES'!AD:AD,0,0) -> 0 | F4: =IF(C4="I",300,IF(C4="II",200,IF(C4="III",100,IF(C4="IV",50)))) -> FALSE
A5: 10106 | B5: Bratislava - Prístavná | C5: =_xlfn.XLOOKUP(A5,'NEW MODEL BY SES'!B:B,'NEW MODEL BY SES'!AC:AC,0,0) -> 0 | D5: =_xlfn.XLOOKUP(A5,'NEW MODEL BY SES'!B:B,'NEW MODEL BY SES'!AD:AD,0,0) -> 0 | F5: =IF(C5="I",300,IF(C5="II",200,IF(C5="III",100,IF(C5="IV",50)))) -> FALSE
A6: 10108 | B6: Bratislava - Rybničná | C6: =_xlfn.XLOOKUP(A6,'NEW MODEL BY SES'!B:B,'NEW MODEL BY SES'!AC:AC,0,0) -> 0 | D6: =_xlfn.XLOOKUP(A6,'NEW MODEL BY SES'!B:B,'NEW MODEL BY SES'!AD:AD,0,0) -> 0 | F6: =IF(C6="I",300,IF(C6="II",200,IF(C6="III",100,IF(C6="IV",50)))) -> FALSE
A7: 10109 | B7: Bratislava - Viedenská cesta | C7: =_xlfn.XLOOKUP(A7,'NEW MODEL BY SES'!B:B,'NEW MODEL BY SES'!AC:AC,0,0) -> 0 | D7: =_xlfn.XLOOKUP(A7,'NEW MODEL BY SES'!B:B,'NEW MODEL BY SES'!AD:AD,0,0) -> 0 | F7: =IF(C7="I",300,IF(C7="II",200,IF(C7="III",100,IF(C7="IV",50)))) -> FALSE
